Workbook

Sheet Forecast
B2: SKU Name | C2: 45658 | D2: 45689 | E2: 45717 | F2: 45748 | G2: 45778 | H2: 45809 | I2: 45839 | J2: 45870 | K2: 45901 | L2: 45931 | M2: 45962 | N2: 45992 | O2: Total 2025 | P2: 46023 | Q2: 46054 | R2: 46082 | S2: 46113 | T2: 46143 | U2: 46174 | V2: 46204 | W2: 46235 | X2: 46266 | Y2: 46296 | Z2: 46327 | AA2: 46357 | AB2: Total 2026 | AC2: 46388 | AD2: 46419 | AE2: 46447 | AF2: 46478 | AG2: 46508 | AH2: 46539 | AI2: 46569 | AJ2: 46600 | AK2: 46631 | AL2: 46661 | AM2: 46692 | AN2: 46722 | AO2: Total 2027
A3: 1kg | B3: Al Fakher Grapes & Mint 1kg | C3: 160 | D3: 230 | E3: 240 | F3: 280 | G3: 350 | H3: 350 | I3: 300 | J3: 300 | K3: 250 | L3: 250 | M3: 250 | N3: 200 | O3: =SUM(C3:N3) -> 3160 | P3: 250 | Q3: 167 | R3: 200 | S3: 250 | T3: 300 | U3: 300 | V3: 300 | W3: 300 | X3: 300 | Y3: 250 | Z3: 250 | AA3: 250 | AB3: =SUM(P3:AA3) -> 3117 | AC3: 250 | AD3: 230 | AE3: =(R3*2%)+R3 -> 204 | AF3: =(S3*2%)+S3 -> 255 | AG3: =(T3*2%)+T3 -> 306 | AH3: =(U3*2%)+U3 -> 306 | AI3: =(V3*2%)+V3 -> 306 | AJ3: =(W3*2%)+W3 -> 306 | AK3: =(X3*2%)+X3 -> 306 | AL3: =(Y3*2%)+Y3 -> 255 | ... AN3: =(AA3*2%)+AA3 -> 255 | AO3: =SUM(AC3:AN3) -> 3234
A4: 1kg | B4: Al Fakher Grapes 1kg | C4: 520 | D4: 670 | E4: 710 | F4: 620 | G4: 850 | H4: 900 | I4: 1000 | J4: 1000 | K4: 600 | L4: 1000 | M4: 676 | N4: 450 | O4: =SUM(C4:N4) -> 8996 | P4: 800 | Q4: 800 | R4: 600 | S4: 500 | T4: 500 | U4: 500 | V4: 500 | W4: 500 | X4: 500 | Y4: 500 | Z4: 400 | AA4: 430 | AB4: =SUM(P4:AA4) -> 6530 | AC4: 800 | AD4: 800 | AE4: =(R4*2%)+R4 -> 612 | AF4: =(S4*2%)+S4 -> 510 | AG4: =(T4*2%)+T4 -> 510 | AH4: =(U4*2%)+U4 -> 510 | AI4: =(V4*2%)+V4 -> 510 | AJ4: =(W4*2%)+W4 -> 510 | AK4: =(X4*2%)+X4 -> 510 | AL4: =(Y4*2%)+Y4 -> 510 | ... AN4: =(AA4*2%)+AA4 -> 438.6 | AO4: =SUM(AC4:AN4) -> 6628.6
A5: 1kg | B5: Al Fakher Lemon Mint 1kg | C5: 320 | D5: 370 | E5: 390 | F5: 410 | G5: 500 | H5: 400 | I5: 500 | J5: 600 | K5: 300 | L5: 450 | M5: 350 | N5: 410 | O5: =SUM(C5:N5) -> 5000 | P5: 300 | Q5: 284 | R5: 400 | S5: 450 | T5: 450 | U5: 450 | V5: 500 | W5: 500 | X5: 500 | Y5: 450 | Z5: 450 | AA5: 350 | AB5: =SUM(P5:AA5) -> 5084 | AC5: 400 | AD5: 400 | AE5: =(R5*2%)+R5 -> 408 | AF5: =(S5*2%)+S5 -> 459 | AG5: =(T5*2%)+T5 -> 459 | AH5: =(U5*2%)+U5 -> 459 | AI5: =(V5*2%)+V5 -> 510 | AJ5: =(W5*2%)+W5 -> 510 | AK5: =(X5*2%)+X5 -> 510 | AL5: =(Y5*2%)+Y5 -> 459 | ... AN5: =(AA5*2%)+AA5 -> 357 | AO5: =SUM(AC5:AN5) -> 5390
A6: 1kg | B6: Al Fakher Mint 1kg | C6: 520 | D6: 670 | E6: 550 | F6: 550 | G6: 750 | H6: 750 | I6: 650 | J6: 650 | K6: 500 | L6: 500 | M6: 500 | N6: 450 | O6: =SUM(C6:N6) -> 7040 | P6: 480 | Q6: 480 | R6: 550 | S6: 450 | T6: 450 | U6: 450 | V6: 450 | W6: 450 | X6: 450 | Y6: 450 | Z6: 450 | AA6: 250 | AB6: =SUM(P6:AA6) -> 5360 | AC6: 550 | AD6: 550 | AE6: =(R6*2%)+R6 -> 561 | AF6: =(S6*2%)+S6 -> 459 | AG6: =(T6*2%)+T6 -> 459 | AH6: =(U6*2%)+U6 -> 459 | AI6: =(V6*2%)+V6 -> 459 | AJ6: =(W6*2%)+W6 -> 459 | AK6: =(X6*2%)+X6 -> 459 | AL6: =(Y6*2%)+Y6 -> 459 | ... AN6: =(AA6*2%)+AA6 -> 255 | AO6: =SUM(AC6:AN6) -> 5588
A7: 1kg | B7: Al Fakher Two apple 1kg | C7: 2900 | D7: 3400 | E7: 3600 | F7: 3200 | G7: 4000 | H7: 4000 | I7: 3500 | J7: 3500 | K7: 4700 | L7: 4500 | M7: 0 | N7: 5000 | O7: =SUM(C7:N7) -> 42300 | P7: 2600 | Q7: 3000 | R7: 3500 | S7: 5000 | T7: 5000 | U7: 5000 | V7: 5500 | W7: 5000 | X7: 5000 | Y7: 4000 | Z7: 4000 | AA7: 3000 | AB7: =SUM(P7:AA7) -> 50600 | AC7: 4000 | AD7: 4000 | AE7: =(R7*2%)+R7 -> 3570 | AF7: =(S7*2%)+S7 -> 5100 | AG7: =(T7*2%)+T7 -> 5100 | AH7: =(U7*2%)+U7 -> 5100 | AI7: =(V7*2%)+V7 -> 5610 | AJ7: =(W7*2%)+W7 -> 5100 | AK7: =(X7*2%)+X7 -> 5100 | AL7: =(Y7*2%)+Y7 -> 4080 | ... AN7: =(AA7*2%)+AA7 -> 3060 | AO7: =SUM(AC7:AN7) -> 53900
A8: 250g | B8: Al Fakher Grapes & Mint 250g | C8: 110 | D8: 120 | E8: 120 | F8: 130 | G8: 160 | H8: 150 | I8: 150 | J8: 150 | K8: 121 | L8: 0 | M8: 164 | N8: 170 | O8: =SUM(C8:N8) -> 1545 | P8: 0 | Q8: 140 | R8: 125 | S8: 150 | T8: 150 | U8: 150 | V8: 125 | W8: 125 | X8: 125 | Y8: 125 | Z8: 125 | AA8: 100 | AB8: =SUM(P8:AA8) -> 1440 | AC8: 125 | AD8: 140 | AE8: =(R8*2%)+R8 -> 127.5 | AF8: =(S8*2%)+S8 -> 153 | AG8: =(T8*2%)+T8 -> 153 | AH8: =(U8*2%)+U8 -> 153 | AI8: =(V8*2%)+V8 -> 127.5 | AJ8: =(W8*2%)+W8 -> 127.5 | AK8: =(X8*2%)+X8 -> 127.5 | AL8: =(Y8*2%)+Y8 -> 127.5 | ... AN8: =(AA8*2%)+AA8 -> 102 | AO8: =SUM(AC8:AN8) -> 1591
A9: 250g | B9: Al Fakher Grapes 250g | C9: 170 | D9: 230 | E9: 240 | F9: 220 | G9: 275 | H9: 260 | I9: 280 | J9: 250 | K9: 400 | L9: 300 | M9: 289 | N9: 200 | O9: =SUM(C9:N9) -> 3114 | P9: 93 | Q9: 100 | R9: 200 | S9: 250 | T9: 250 | U9: 250 | V9: 200 | W9: 200 | X9: 200 | Y9: 200 | Z9: 200 | AA9: 150 | AB9: =SUM(P9:AA9) -> 2293 | AC9: 250 | AD9: 200 | AE9: =(R9*2%)+R9 -> 204 | AF9: =(S9*2%)+S9 -> 255 | AG9: =(T9*2%)+T9 -> 255 | AH9: =(U9*2%)+U9 -> 255 | AI9: =(V9*2%)+V9 -> 204 | AJ9: =(W9*2%)+W9 -> 204 | AK9: =(X9*2%)+X9 -> 204 | AL9: =(Y9*2%)+Y9 -> 204 | ... AN9: =(AA9*2%)+AA9 -> 153 | AO9: =SUM(AC9:AN9) -> 2592
A10: 250g | B10: Al Fakher Lemon Mint 250g | C10: 130 | D10: 150 | E10: 160 | F10: 200 | G10: 240 | H10: 230 | I10: 240 | J10: 250 | K10: 250 | L10: 200 | M10: 200 | N10: 200 | O10: =SUM(C10:N10) -> 2450 | P10: 100 | Q10: 175 | R10: 175 | S10: 175 | T10: 175 | U10: 200 | V10: 200 | W10: 200 | X10: 200 | Y10: 175 | Z10: 150 | AA10: 150 | AB10: =SUM(P10:AA10) -> 2075 | AC10: 175 | AD10: 175 | AE10: =(R10*2%)+R10 -> 178.5 | AF10: =(S10*2%)+S10 -> 178.5 | AG10: =(T10*2%)+T10 -> 178.5 | AH10: =(U10*2%)+U10 -> 204 | AI10: =(V10*2%)+V10 -> 204 | AJ10: =(W10*2%)+W10 -> 204 | AK10: =(X10*2%)+X10 -> 204 | AL10: =(Y10*2%)+Y10 -> 178.5 | ... AN10: =(AA10*2%)+AA10 -> 153 | AO10: =SUM(AC10:AN10) -> 2186
A11: 250g | B11: Al Fakher Two apple 250g | C11: 2300 | D11: 2500 | E11: 2700 | F11: 2400 | G11: 3250 | H11: 3000 | I11: 3500 | J11: 4000 | K11: 1500 | L11: 3500 | M11: 5000 | N11: 1270 | O11: =SUM(C11:N11) -> 34920 | P11: 5500 | Q11: 5000 | R11: 5000 | S11: 4500 | T11: 4500 | U11: 4500 | V11: 5000 | W11: 5000 | X11: 3500 | Y11: 3500 | Z11: 3500 | AA11: 3000 | AB11: =SUM(P11:AA11) -> 52500 | AC11: 5500 | AD11: 5000 | AE11: =(R11*2%)+R11 -> 5100 | AF11: =(S11*2%)+S11 -> 4590 | AG11: =(T11*2%)+T11 -> 4590 | AH11: =(U11*2%)+U11 -> 4590 | AI11: =(V11*2%)+V11 -> 5100 | AJ11: =(W11*2%)+W11 -> 5100 | AK11: =(X11*2%)+X11 -> 3570 | AL11: =(Y11*2%)+Y11 -> 3570 | ... AN11: =(AA11*2%)+AA11 -> 3060 | AO11: =SUM(AC11:AN11) -> 53340
A12: 250g | B12: Al Fakher Two Apple Bahraini 250g | C12: 180 | D12: 180 | E12: 190 | F12: 250 | G12: 320 | H12: 300 | I12: 300 | J12: 300 | K12: 300 | L12: 300 | M12: 300 | N12: 250 | O12: =SUM(C12:N12) -> 3170 | P12: 150 | Q12: 200 | R12: 200 | S12: 300 | T12: 250 | U12: 250 | V12: 250 | W12: 250 | X12: 250 | Y12: 200 | Z12: 200 | AA12: 200 | AB12: =SUM(P12:AA12) -> 2700 | AC12: 200 | AD12: 200 | AE12: =(R12*2%)+R12 -> 204 | AF12: =(S12*2%)+S12 -> 306 | AG12: =(T12*2%)+T12 -> 255 | AH12: =(U12*2%)+U12 -> 255 | AI12: =(V12*2%)+V12 -> 255 | AJ12: =(W12*2%)+W12 -> 255 | AK12: =(X12*2%)+X12 -> 255 | AL12: =(Y12*2%)+Y12 -> 204 | ... AN12: =(AA12*2%)+AA12 -> 204 | AO12: =SUM(AC12:AN12) -> 2797
A13: 50g | B13: Al Fakher Blueberry Mint 50g | C13: 20 | D13: 10 | E13: 10 | F13: 20 | G13: 10 | H13: 10 | I13: 0 | J13: 0 | K13: 0 | L13: 0 | M13: 0 | N13: - | O13: =SUM(C13:N13) -> 80 | P13: - | Q13: - | R13: - | S13: 0 | T13: 0 | U13: 0 | V13: 0 | W13: 0 | X13: 0 | Y13: 0 | Z13: 0 | AA13: 0 | AB13: =SUM(P13:AA13) -> 0 | AC13: 0 | AD13: 0 | AE13: 0 | AF13: =(S13*2%)+S13 -> 0 | AG13: =(T13*2%)+T13 -> 0 | AH13: =(U13*2%)+U13 -> 0 | AI13: =(V13*2%)+V13 -> 0 | AJ13: =(W13*2%)+W13 -> 0 | AK13: =(X13*2%)+X13 -> 0 | AL13: =(Y13*2%)+Y13 -> 0 | AM13: =(Z13*2%)+Z13 -> 0 | AN13: =(AA13*2%)+AA13 -> 0 | AO13: =SUM(AC13:AN13) -> 0
A14: 50g | B14: Al Fakher Blueberry 50g | C14: 30 | D14: 40 | E14: 40 | F14: 40 | G14: 50 | H14: 40 | I14: 40 | J14: 40 | K14: 0 | L14: 100 | M14: 50 | N14: - | O14: =SUM(C14:N14) -> 470 | P14: 75 | Q14: 75 | R14: 30 | S14: 30 | T14: 60 | U14: 60 | V14: 60 | W14: 60 | X14: 60 | Y14: 60 | Z14: 60 | AA14: 30 | AB14: =SUM(P14:AA14) -> 660 | AC14: 150 | AD14: 75 | AE14: =(R14*2%)+R14 -> 30.6 | AF14: =(S14*2%)+S14 -> 30.6 | AG14: =(T14*2%)+T14 -> 61.2 | AH14: =(U14*2%)+U14 -> 61.2 | AI14: =(V14*2%)+V14 -> 61.2 | AJ14: =(W14*2%)+W14 -> 61.2 | AK14: =(X14*2%)+X14 -> 61.2 | AL14: =(Y14*2%)+Y14 -> 61.2 | ... AN14: =(AA14*2%)+AA14 -> 30.6 | AO14: =SUM(AC14:AN14) -> 745.2
A15: 50g | B15: Al Fakher Buble Gum 50g | C15: 10 | D15: 10 | E15: 10 | F15: 10 | G15: 5 | H15: 5 | I15: 0 | J15: 0 | K15: 0 | L15: 0 | M15: 0 | N15: - | O15: =SUM(C15:N15) -> 50 | P15: - | Q15: - | R15: - | S15: 0 | T15: 0 | U15: 0 | V15: 0 | W15: 0 | X15: 0 | Y15: 0 | Z15: 0 | AA15: 0 | AB15: =SUM(P15:AA15) -> 0 | AC15: 0 | AD15: 0 | AE15: 0 | AF15: =(S15*2%)+S15 -> 0 | AG15: =(T15*2%)+T15 -> 0 | AH15: =(U15*2%)+U15 -> 0 | AI15: =(V15*2%)+V15 -> 0 | AJ15: =(W15*2%)+W15 -> 0 | AK15: =(X15*2%)+X15 -> 0 | AL15: =(Y15*2%)+Y15 -> 0 | AM15: =(Z15*2%)+Z15 -> 0 | AN15: =(AA15*2%)+AA15 -> 0 | AO15: =SUM(AC15:AN15) -> 0
A16: 50g | B16: Al Fakher Grapes & Mint 50g | C16: 130 | D16: 190 | E16: 180 | F16: 180 | G16: 220 | H16: 200 | I16: 200 | J16: 200 | K16: 200 | L16: 200 | M16: 200 | N16: 250 | O16: =SUM(C16:N16) -> 2350 | P16: 158 | Q16: 100 | R16: 230 | S16: 243 | T16: 139 | U16: 270 | V16: 270 | W16: 270 | X16: 250 | Y16: 250 | Z16: 200 | AA16: 200 | AB16: =SUM(P16:AA16) -> 2580 | AC16: 230 | AD16: 230 | AE16: =(R16*2%)+R16 -> 234.6 | AF16: =(S16*2%)+S16 -> 247.86 | AG16: =(T16*2%)+T16 -> 141.78 | AH16: =(U16*2%)+U16 -> 275.4 | AI16: =(V16*2%)+V16 -> 275.4 | AJ16: =(W16*2%)+W16 -> 275.4 | AK16: =(X16*2%)+X16 -> 255 | AL16: =(Y16*2%)+Y16 -> 255 | ... AN16: =(AA16*2%)+AA16 -> 204 | AO16: =SUM(AC16:AN16) -> 2828.44
A17: 50g | B17: Al Fakher Grapes 50g | C17: 210 | D17: 340 | E17: 320 | F17: 310 | G17: 375 | H17: 360 | I17: 450 | J17: 450 | K17: 151 | L17: 400 | M17: 300 | N17: 250 | O17: =SUM(C17:N17) -> 3916 | P17: 393 | Q17: 92 | R17: 360 | S17: 450 | T17: 450 | U17: 450 | V17: 400 | W17: 400 | X17: 400 | Y17: 350 | Z17: 300 | AA17: 250 | AB17: =SUM(P17:AA17) -> 4295 | AC17: 400 | AD17: 400 | AE17: =(R17*2%)+R17 -> 367.2 | AF17: =(S17*2%)+S17 -> 459 | AG17: =(T17*2%)+T17 -> 459 | AH17: =(U17*2%)+U17 -> 459 | AI17: =(V17*2%)+V17 -> 408 | AJ17: =(W17*2%)+W17 -> 408 | AK17: =(X17*2%)+X17 -> 408 | AL17: =(Y17*2%)+Y17 -> 357 | ... AN17: =(AA17*2%)+AA17 -> 255 | AO17: =SUM(AC17:AN17) -> 4686.2
A18: 50g | B18: Al Fakher Gum Mint 50g | C18: 100 | D18: 80 | E18: 80 | F18: 70 | G18: 100 | H18: 100 | I18: 90 | J18: 90 | K18: 120 | L18: 80 | M18: 80 | N18: 80 | O18: =SUM(C18:N18) -> 1070 | P18: 155 | Q18: 25 | R18: 25 | S18: 75 | T18: 100 | U18: 100 | V18: 100 | W18: 100 | X18: 75 | Y18: 75 | Z18: 75 | AA18: 75 | AB18: =SUM(P18:AA18) -> 980 | AC18: 200 | AD18: 150 | AE18: =(R18*2%)+R18 -> 25.5 | AF18: =(S18*2%)+S18 -> 76.5 | AG18: =(T18*2%)+T18 -> 102 | AH18: =(U18*2%)+U18 -> 102 | AI18: =(V18*2%)+V18 -> 102 | AJ18: =(W18*2%)+W18 -> 102 | AK18: =(X18*2%)+X18 -> 76.5 | AL18: =(Y18*2%)+Y18 -> 76.5 | ... AN18: =(AA18*2%)+AA18 -> 76.5 | AO18: =SUM(AC18:AN18) -> 1166
A19: 50g | B19: Al Fakher Gum 50g | C19: 10 | D19: 10 | E19: 10 | F19: 10 | G19: 15 | H19: 10 | I19: 0 | J19: 0 | K19: 20 | L19: 15 | M19: 15 | N19: 25 | O19: =SUM(C19:N19) -> 140 | P19: 20 | Q19: 20 | R19: 7 | S19: 50 | T19: 50 | U19: 40 | V19: 40 | W19: 40 | X19: 40 | Y19: 30 | Z19: 30 | AA19: 20 | AB19: =SUM(P19:AA19) -> 387 | AC19: 20 | AD19: 20 | AE19: =(R19*2%)+R19 -> 7.14 | AF19: =(S19*2%)+S19 -> 51 | AG19: =(T19*2%)+T19 -> 51 | AH19: =(U19*2%)+U19 -> 40.8 | AI19: =(V19*2%)+V19 -> 40.8 | AJ19: =(W19*2%)+W19 -> 40.8 | AK19: =(X19*2%)+X19 -> 40.8 | AL19: =(Y19*2%)+Y19 -> 30.6 | ... AN19: =(AA19*2%)+AA19 -> 20.4 | AO19: =SUM(AC19:AN19) -> 393.94
A20: 50g | B20: Al Fakher Lemon Mint 50g | C20: 210 | D20: 300 | E20: 320 | F20: 310 | G20: 375 | H20: 400 | I20: 350 | J20: 350 | K20: 250 | L20: 250 | M20: 250 | N20: 250 | O20: =SUM(C20:N20) -> 3615 | P20: 0 | Q20: 137 | R20: 150 | S20: 300 | T20: 400 | U20: 400 | V20: 350 | W20: 350 | X20: 350 | Y20: 250 | Z20: 250 | AA20: 250 | AB20: =SUM(P20:AA20) -> 3187 | AC20: 250 | AD20: 250 | AE20: =(R20*2%)+R20 -> 153 | AF20: =(S20*2%)+S20 -> 306 | AG20: =(T20*2%)+T20 -> 408 | AH20: =(U20*2%)+U20 -> 408 | AI20: =(V20*2%)+V20 -> 357 | AJ20: =(W20*2%)+W20 -> 357 | AK20: =(X20*2%)+X20 -> 357 | AL20: =(Y20*2%)+Y20 -> 255 | ... AN20: =(AA20*2%)+AA20 -> 255 | AO20: =SUM(AC20:AN20) -> 3611
A21: 50g | B21: Al Fakher Magic Love 50g | C21: 40 | D21: 60 | E21: 60 | F21: 60 | G21: 50 | H21: 50 | I21: 0 | J21: 0 | K21: 60 | L21: 50 | M21: 50 | N21: 35 | O21: =SUM(C21:N21) -> 515 | P21: 30 | Q21: 30 | R21: 70 | S21: 50 | T21: 40 | U21: 80 | V21: 80 | W21: 80 | X21: 75 | Y21: 75 | Z21: 50 | AA21: 50 | AB21: =SUM(P21:AA21) -> 710 | AC21: 30 | AD21: 30 | AE21: =(R21*2%)+R21 -> 71.4 | AF21: =(S21*2%)+S21 -> 51 | AG21: =(T21*2%)+T21 -> 40.8 | AH21: =(U21*2%)+U21 -> 81.6 | AI21: =(V21*2%)+V21 -> 81.6 | AJ21: =(W21*2%)+W21 -> 81.6 | AK21: =(X21*2%)+X21 -> 76.5 | AL21: =(Y21*2%)+Y21 -> 76.5 | ... AN21: =(AA21*2%)+AA21 -> 51 | AO21: =SUM(AC21:AN21) -> 723
A22: 50g | B22: Al Fakher Mint 50g | C22: 320 | D22: 370 | E22: 390 | F22: 410 | G22: 500 | H22: 480 | I22: 500 | J22: 500 | K22: 350 | L22: 350 | M22: 350 | N22: 220 | O22: =SUM(C22:N22) -> 4740 | P22: 160 | Q22: 0 | R22: 300 | S22: 400 | T22: 400 | U22: 400 | V22: 400 | W22: 400 | X22: 400 | Y22: 300 | Z22: 300 | AA22: 200 | AB22: =SUM(P22:AA22) -> 3660 | AC22: 400 | AD22: 300 | AE22: =(R22*2%)+R22 -> 306 | AF22: =(S22*2%)+S22 -> 408 | AG22: =(T22*2%)+T22 -> 408 | AH22: =(U22*2%)+U22 -> 408 | AI22: =(V22*2%)+V22 -> 408 | AJ22: =(W22*2%)+W22 -> 408 | AK22: =(X22*2%)+X22 -> 408 | AL22: =(Y22*2%)+Y22 -> 306 | ... AN22: =(AA22*2%)+AA22 -> 204 | AO22: =SUM(AC22:AN22) -> 4270
A23: 50g | B23: Al Fakher Two apple 50g | C23: 3200 | D23: 5100 | E23: 4600 | F23: 5300 | G23: 6750 | H23: 6500 | I23: 6250 | J23: 6500 | K23: 6500 | L23: 5000 | M23: 7500 | N23: 6900 | O23: =SUM(C23:N23) -> 70100 | P23: 7500 | Q23: 8000 | R23: 9000 | S23: 7500 | T23: 6500 | U23: 6500 | V23: 7000 | W23: 7000 | X23: 6500 | Y23: 6500 | Z23: 6000 | AA23: 4500 | AB23: =SUM(P23:AA23) -> 82500 | AC23: 7500 | AD23: 8000 | AE23: =(R23*2%)+R23 -> 9180 | AF23: =(S23*2%)+S23 -> 7650 | AG23: =(T23*2%)+T23 -> 6630 | AH23: =(U23*2%)+U23 -> 6630 | AI23: =(V23*2%)+V23 -> 7140 | AJ23: =(W23*2%)+W23 -> 7140 | AK23: =(X23*2%)+X23 -> 6630 | AL23: =(Y23*2%)+Y23 -> 6630 | ... AN23: =(AA23*2%)+AA23 -> 4590 | AO23: =SUM(AC23:AN23) -> 83840
A24: 50g | B24: Lemonade Mint 50g | O24: =SUM(C24:N24) -> 0 | P24: 0 | Q24: 0 | R24: 0 | S24: 0 | T24: 0 | U24: 0 | V24: 0 | W24: 0 | X24: 0 | Y24: 0 | Z24: 0 | AA24: 0 | AB24: =SUM(P24:AA24) -> 0 | AO24: =SUM(AC24:AN24) -> 0
A25: 50g | B25: Lemonade Pear 50g | O25: =SUM(C25:N25) -> 0 | P25: 0 | Q25: 0 | R25: 0 | S25: 0 | T25: 0 | U25: 0 | V25: 0 | W25: 0 | X25: 0 | Y25: 0 | Z25: 0 | AA25: 0 | AB25: =SUM(P25:AA25) -> 0 | AO25: =SUM(AC25:AN25) -> 0
A26: 50g | B26: Al Fakher Double Apple Classic 50g | P26: 0 | Q26: 0 | R26: 0 | S26: 0 | T26: 0 | U26: 0 | V26: 0 | W26: 0 | X26: 0 | Y26: 0 | Z26: 0 | AA26: 0 | AB26: =SUM(P26:AA26) -> 0 | AO26: =SUM(AC26:AN26) -> 0
A27: 250g | B27: Al Fakher Double Apple Classic 250g | P27: 0 | Q27: 0 | R27: 0 | S27: 0 | T27: 0 | U27: 0 | V27: 0 | W27: 0 | X27: 0 | Y27: 0 | Z27: 0 | AA27: 0 | AB27: =SUM(P27:AA27) -> 0 | AO27: =SUM(AC27:AN27) -> 0
A28: 1kg | B28: Al Fakher Double Apple Classic 1Kg | P28: 0 | Q28: 0 | R28: 0 | S28: 0 | T28: 0 | U28: 0 | V28: 0 | W28: 0 | X28: 0 | Y28: 300 | Z28: 300 | AA28: 300 | AB28: =SUM(P28:AA28) -> 900 | AC28: 300 | AD28: 300 | AE28: 300 | AF28: 300 | AG28: 300 | AH28: 300 | AI28: 300 | AJ28: 300 | AK28: 300 | AL28: 300 | AM28: 300 | AN28: 300 | AO28: =SUM(AC28:AN28) -> 3600
A29: 50g | B29: Al Fakher Italian Lemon Mint 50g | P29: 0 | Q29: 0 | R29: 0 | S29: 0 | T29: 0 | U29: 0 | V29: 0 | W29: 0 | X29: 0 | Y29: 250 | Z29: 250 | AA29: 250 | AB29: =SUM(P29:AA29) -> 750 | AC29: 350 | AD29: 250 | AE29: =AD29*1.05 -> 262.5 | AF29: =AE29*1.05 -> 275.625 | AG29: =AF29*1.05 -> 289.40625 | AH29: =AG29*1.05 -> 303.87656 | AI29: =AH29*1.05 -> 319.07039 | AJ29: =AI29*1.05 -> 335.02391 | AK29: =AJ29*1.05 -> 351.77511 | AL29: 250 | AM29: 250 | AN29: 250 | AO29: =SUM(AC29:AN29) -> 3487.2772
A30: 250g | B30: Al Fakher Italian Lemon Mint 250g | P30: 0 | Q30: 0 | R30: 0 | S30: 0 | T30: 0 | U30: 0 | V30: 0 | W30: 0 | X30: 0 | Y30: 150 | Z30: 150 | AA30: 150 | AB30: =SUM(P30:AA30) -> 450 | AC30: 200 | AD30: 200 | AE30: =AD30*1.05 -> 210 | AF30: =AE30*1.05 -> 220.5 | AG30: =AF30*1.05 -> 231.525 | AH30: =AG30*1.05 -> 243.10125 | AI30: =AH30*1.05 -> 255.25631 | AJ30: =AI30*1.05 -> 268.01913 | AK30: =AJ30*1.05 -> 281.42008 | AL30: 200 | AM30: 200 | AN30: 200 | AO30: =SUM(AC30:AN30) -> 2709.8218
A31: 1kg | B31: Al Fakher Italian Lemon Mint 1Kg | P31: 0 | Q31: 0 | R31: 0 | S31: 0 | T31: 0 | U31: 0 | V31: 0 | W31: 0 | X31: 0 | Y31: 200 | Z31: 200 | AA31: 200 | AB31: =SUM(P31:AA31) -> 600 | AC31: 250 | AD31: 200 | AE31: =AD31*1.05 -> 210 | AF31: =AE31*1.05 -> 220.5 | AG31: =AF31*1.05 -> 231.525 | AH31: =AG31*1.05 -> 243.10125 | AI31: =AH31*1.05 -> 255.25631 | AJ31: =AI31*1.05 -> 268.01913 | AK31: =AJ31*1.05 -> 281.42008 | AL31: 200 | AM31: 200 | AN31: 200 | AO31: =SUM(AC31:AN31) -> 2759.8218
B32: Total without Classic & Italian | C32: =SUM(C3:C23) -> 11590 | D32: =SUM(D3:D23) -> 15030 | E32: =SUM(E3:E23) -> 14920 | F32: =SUM(F3:F23) -> 14980 | G32: =SUM(G3:G23) -> 19145 | H32: =SUM(H3:H23) -> 18495 | I32: =SUM(I3:I23) -> 18300 | J32: =SUM(J3:J23) -> 19130 | ... AO32: =SUM(AO3:AO23) -> 239510.38
AB33: =AB32*6 -> 1383948
B34: Total with Classic & Italian | C34: =SUM(C3:C31) -> 11590 | D34: =SUM(D3:D31) -> 15030 | E34: =SUM(E3:E31) -> 14920 | F34: =SUM(F3:F31) -> 14980 | G34: =SUM(G3:G31) -> 19145 | H34: =SUM(H3:H31) -> 18495 | I34: =SUM(I3:I31) -> 18300 | J34: =SUM(J3:J31) -> 19130 | ... AO34: =SUM(AO3:AO31) -> 252067.3
AB35: =AB34*6 -> 1400148
AB37: =1450000/6 -> 241666.67
K39: =68368*6 -> 410208
K41: =77000*6 -> 462000

Sheet IMS vs FRCST
B2: SKU Name | C2: 45658 | D2: 45689 | E2: 45717 | F2: 45748 | G2: 45778 | H2: 45809 | I2: 45839 | J2: 45870 | K2: 45901 | L2: 45931 | M2: 45962 | N2: 45992 | O2: Total 2025 | P2: 46023 | Q2: 46054 | R2: 46082 | S2: 46113 | T2: 46143 | U2: 46174 | V2: 46204 | W2: 46235 | X2: 46266 | Y2: 46296 | Z2: 46327 | AA2: 46357 | AB2: Total 2026 | AC2: 46388 | AD2: 46419 | AE2: 46447 | AF2: 46478 | AG2: 46508 | AH2: 46539 | AI2: 46569 | AJ2: 46600 | AK2: 46631 | AL2: 46661 | AM2: 46692 | AN2: 46722 | AO2: Total 2027
A3: 1kg | B3: =Forecast!B3 -> Al Fakher Grapes & Mint 1kg | C3: 203 | D3: 47 | E3: 419 | F3: 207 | G3: 144 | H3: 156 | I3: 495 | J3: 172 | K3: 244 | L3: 637 | M3: 101 | N3: 2 | O3: =SUM(C3:N3) -> 2827 | P3: 292 | Q3: 84 | R3: 65 | S3: =Forecast!S3 -> 250 | T3: =Forecast!T3 -> 300 | U3: =Forecast!U3 -> 300 | V3: =Forecast!V3 -> 300 | W3: =Forecast!W3 -> 300 | X3: =Forecast!X3 -> 300 | Y3: =Forecast!Y3 -> 250 | Z3: =Forecast!Z3 -> 250 | AA3: =Forecast!AA3 -> 250 | AB3: =SUM(P3:AA3) -> 2941 | AC3: =Forecast!AC3 -> 250 | AD3: =Forecast!AD3 -> 230 | AE3: =Forecast!AE3 -> 204 | AF3: =Forecast!AF3 -> 255 | AG3: =Forecast!AG3 -> 306 | AH3: =Forecast!AH3 -> 306 | AI3: =Forecast!AI3 -> 306 | AJ3: =Forecast!AJ3 -> 306 | ... AN3: =Forecast!AN3 -> 255 | AO3: =SUM(AC3:AN3) -> 3234 | AP3: =AB3/O3-1 -> 0.040325433
A4: 1kg | B4: =Forecast!B4 -> Al Fakher Grapes 1kg | C4: 685 | D4: 967 | E4: 1041 | F4: 6 | G4: 0 | H4: 185 | I4: 1226 | J4: 60 | K4: 656 | L4: 890 | M4: 716 | N4: 22 | O4: =SUM(C4:N4) -> 6454 | P4: 505 | Q4: 115 | R4: 128 | S4: =Forecast!S4 -> 500 | T4: =Forecast!T4 -> 500 | U4: =Forecast!U4 -> 500 | V4: =Forecast!V4 -> 500 | W4: =Forecast!W4 -> 500 | X4: =Forecast!X4 -> 500 | Y4: =Forecast!Y4 -> 500 | Z4: =Forecast!Z4 -> 400 | AA4: =Forecast!AA4 -> 430 | AB4: =SUM(P4:AA4) -> 5078 | AC4: =Forecast!AC4 -> 800 | AD4: =Forecast!AD4 -> 800 | AE4: =Forecast!AE4 -> 612 | AF4: =Forecast!AF4 -> 510 | AG4: =Forecast!AG4 -> 510 | AH4: =Forecast!AH4 -> 510 | AI4: =Forecast!AI4 -> 510 | AJ4: =Forecast!AJ4 -> 510 | ... AN4: =Forecast!AN4 -> 438.6 | AO4: =SUM(AC4:AN4) -> 6628.6 | AP4: =AB4/O4-1 -> -0.21320112
A5: 1kg | B5: =Forecast!B5 -> Al Fakher Lemon Mint 1kg | C5: 165 | D5: 9 | E5: 587 | F5: 313 | G5: 195 | H5: 242 | I5: 489 | J5: 343 | K5: 348 | L5: 553 | M5: 457 | N5: 85 | O5: =SUM(C5:N5) -> 3786 | P5: 377 | Q5: 138 | R5: 94 | S5: =Forecast!S5 -> 450 | T5: =Forecast!T5 -> 450 | U5: =Forecast!U5 -> 450 | V5: =Forecast!V5 -> 500 | W5: =Forecast!W5 -> 500 | X5: =Forecast!X5 -> 500 | Y5: =Forecast!Y5 -> 450 | Z5: =Forecast!Z5 -> 450 | AA5: =Forecast!AA5 -> 350 | AB5: =SUM(P5:AA5) -> 4709 | AC5: =Forecast!AC5 -> 400 | AD5: =Forecast!AD5 -> 400 | AE5: =Forecast!AE5 -> 408 | AF5: =Forecast!AF5 -> 459 | AG5: =Forecast!AG5 -> 459 | AH5: =Forecast!AH5 -> 459 | AI5: =Forecast!AI5 -> 510 | AJ5: =Forecast!AJ5 -> 510 | ... AN5: =Forecast!AN5 -> 357 | AO5: =SUM(AC5:AN5) -> 5390 | AP5: =AB5/O5-1 -> 0.24379292
A6: 1kg | B6: =Forecast!B6 -> Al Fakher Mint 1kg | C6: 702 | D6: 198 | E6: 920 | F6: 200 | G6: 344 | H6: 65 | I6: 515 | J6: 348 | K6: 406 | L6: 644 | M6: 609 | N6: 56 | O6: =SUM(C6:N6) -> 5007 | P6: 300 | Q6: 49 | R6: 86 | S6: =Forecast!S6 -> 450 | T6: =Forecast!T6 -> 450 | U6: =Forecast!U6 -> 450 | V6: =Forecast!V6 -> 450 | W6: =Forecast!W6 -> 450 | X6: =Forecast!X6 -> 450 | Y6: =Forecast!Y6 -> 450 | Z6: =Forecast!Z6 -> 450 | AA6: =Forecast!AA6 -> 250 | AB6: =SUM(P6:AA6) -> 4285 | AC6: =Forecast!AC6 -> 550 | AD6: =Forecast!AD6 -> 550 | AE6: =Forecast!AE6 -> 561 | AF6: =Forecast!AF6 -> 459 | AG6: =Forecast!AG6 -> 459 | AH6: =Forecast!AH6 -> 459 | AI6: =Forecast!AI6 -> 459 | AJ6: =Forecast!AJ6 -> 459 | ... AN6: =Forecast!AN6 -> 255 | AO6: =SUM(AC6:AN6) -> 5588 | AP6: =AB6/O6-1 -> -0.14419812
A7: 1kg | B7: =Forecast!B7 -> Al Fakher Two apple 1kg | C7: 0 | D7: 5157 | E7: 4029 | F7: 7101 | G7: 0 | H7: 870 | I7: 2311 | J7: 5000 | K7: 3353 | L7: 9975 | M7: 1155 | N7: 4888 | O7: =SUM(C7:N7) -> 43839 | P7: 2699 | Q7: 3455 | R7: 5574 | S7: =Forecast!S7 -> 5000 | T7: =Forecast!T7 -> 5000 | U7: =Forecast!U7 -> 5000 | V7: =Forecast!V7 -> 5500 | W7: =Forecast!W7 -> 5000 | X7: =Forecast!X7 -> 5000 | Y7: =Forecast!Y7 -> 4000 | Z7: =Forecast!Z7 -> 4000 | AA7: =Forecast!AA7 -> 3000 | AB7: =SUM(P7:AA7) -> 53228 | AC7: =Forecast!AC7 -> 4000 | AD7: =Forecast!AD7 -> 4000 | AE7: =Forecast!AE7 -> 3570 | AF7: =Forecast!AF7 -> 5100 | AG7: =Forecast!AG7 -> 5100 | AH7: =Forecast!AH7 -> 5100 | AI7: =Forecast!AI7 -> 5610 | AJ7: =Forecast!AJ7 -> 5100 | ... AN7: =Forecast!AN7 -> 3060 | AO7: =SUM(AC7:AN7) -> 53900 | AP7: =AB7/O7-1 -> 0.21417003
A8: 250g | B8: =Forecast!B8 -> Al Fakher Grapes & Mint 250g | C8: 17 | D8: 21 | E8: 170 | F8: 131 | G8: 119 | H8: 120 | I8: 186 | J8: 177 | K8: 121 | L8: 128 | M8: 45 | N8: 52 | O8: =SUM(C8:N8) -> 1287 | P8: 173 | Q8: 95 | R8: 113 | S8: =Forecast!S8 -> 150 | T8: =Forecast!T8 -> 150 | U8: =Forecast!U8 -> 150 | V8: =Forecast!V8 -> 125 | W8: =Forecast!W8 -> 125 | X8: =Forecast!X8 -> 125 | Y8: =Forecast!Y8 -> 125 | Z8: =Forecast!Z8 -> 125 | AA8: =Forecast!AA8 -> 100 | AB8: =SUM(P8:AA8) -> 1556 | AC8: =Forecast!AC8 -> 125 | AD8: =Forecast!AD8 -> 140 | AE8: =Forecast!AE8 -> 127.5 | AF8: =Forecast!AF8 -> 153 | AG8: =Forecast!AG8 -> 153 | AH8: =Forecast!AH8 -> 153 | AI8: =Forecast!AI8 -> 127.5 | AJ8: =Forecast!AJ8 -> 127.5 | ... AN8: =Forecast!AN8 -> 102 | AO8: =SUM(AC8:AN8) -> 1591 | AP8: =AB8/O8-1 -> 0.20901321
A9: 250g | B9: =Forecast!B9 -> Al Fakher Grapes 250g | C9: 0 | D9: 411 | E9: 381 | F9: 179 | G9: 0 | H9: 331 | I9: 58 | J9: 0 | K9: 463 | L9: 343 | M9: 170 | N9: 31 | O9: =SUM(C9:N9) -> 2367 | P9: 234 | Q9: 48 | R9: 69 | S9: =Forecast!S9 -> 250 | T9: =Forecast!T9 -> 250 | U9: =Forecast!U9 -> 250 | V9: =Forecast!V9 -> 200 | W9: =Forecast!W9 -> 200 | X9: =Forecast!X9 -> 200 | Y9: =Forecast!Y9 -> 200 | Z9: =Forecast!Z9 -> 200 | AA9: =Forecast!AA9 -> 150 | AB9: =SUM(P9:AA9) -> 2251 | AC9: =Forecast!AC9 -> 250 | AD9: =Forecast!AD9 -> 200 | AE9: =Forecast!AE9 -> 204 | AF9: =Forecast!AF9 -> 255 | AG9: =Forecast!AG9 -> 255 | AH9: =Forecast!AH9 -> 255 | AI9: =Forecast!AI9 -> 204 | AJ9: =Forecast!AJ9 -> 204 | ... AN9: =Forecast!AN9 -> 153 | AO9: =SUM(AC9:AN9) -> 2592 | AP9: =AB9/O9-1 -> -0.049007182
A10: 250g | B10: =Forecast!B10 -> Al Fakher Lemon Mint 250g | C10: 0 | D10: 2 | E10: 191 | F10: 233 | G10: 144 | H10: 150 | I10: 133 | J10: 270 | K10: 97 | L10: 308 | M10: 118 | N10: 50 | O10: =SUM(C10:N10) -> 1696 | P10: 245 | Q10: 119 | R10: 82 | S10: =Forecast!S10 -> 175 | T10: =Forecast!T10 -> 175 | U10: =Forecast!U10 -> 200 | V10: =Forecast!V10 -> 200 | W10: =Forecast!W10 -> 200 | X10: =Forecast!X10 -> 200 | Y10: =Forecast!Y10 -> 175 | Z10: =Forecast!Z10 -> 150 | AA10: =Forecast!AA10 -> 150 | AB10: =SUM(P10:AA10) -> 2071 | AC10: =Forecast!AC10 -> 175 | AD10: =Forecast!AD10 -> 175 | AE10: =Forecast!AE10 -> 178.5 | AF10: =Forecast!AF10 -> 178.5 | AG10: =Forecast!AG10 -> 178.5 | AH10: =Forecast!AH10 -> 204 | AI10: =Forecast!AI10 -> 204 | AJ10: =Forecast!AJ10 -> 204 | ... AN10: =Forecast!AN10 -> 153 | AO10: =SUM(AC10:AN10) -> 2186 | AP10: =AB10/O10-1 -> 0.22110849
A11: 250g | B11: =Forecast!B11 -> Al Fakher Two apple 250g | C11: 3023 | D11: 2253 | E11: 2242 | F11: 4299 | G11: 0 | H11: 2351 | I11: 998 | J11: 6457 | K11: 3376 | L11: 4915 | M11: 7421 | N11: 0 | O11: =SUM(C11:N11) -> 37335 | P11: 6920 | Q11: 3648 | R11: 4177 | S11: =Forecast!S11 -> 4500 | T11: =Forecast!T11 -> 4500 | U11: =Forecast!U11 -> 4500 | V11: =Forecast!V11 -> 5000 | W11: =Forecast!W11 -> 5000 | X11: =Forecast!X11 -> 3500 | Y11: =Forecast!Y11 -> 3500 | Z11: =Forecast!Z11 -> 3500 | AA11: =Forecast!AA11 -> 3000 | AB11: =SUM(P11:AA11) -> 51745 | AC11: =Forecast!AC11 -> 5500 | AD11: =Forecast!AD11 -> 5000 | AE11: =Forecast!AE11 -> 5100 | AF11: =Forecast!AF11 -> 4590 | AG11: =Forecast!AG11 -> 4590 | AH11: =Forecast!AH11 -> 4590 | AI11: =Forecast!AI11 -> 5100 | AJ11: =Forecast!AJ11 -> 5100 | ... AN11: =Forecast!AN11 -> 3060 | AO11: =SUM(AC11:AN11) -> 53340 | AP11: =AB11/O11-1 -> 0.38596491
A12: 250g | B12: =Forecast!B12 -> Al Fakher Two Apple Bahraini 250g | C12: 300 | D12: 0 | E12: 555 | F12: 79 | G12: 8 | H12: 264 | I12: 58 | J12: 60 | K12: 537 | L12: 94 | M12: 400 | N12: 50 | O12: =SUM(C12:N12) -> 2405 | P12: 229 | Q12: 26 | R12: 58 | S12: =Forecast!S12 -> 300 | T12: =Forecast!T12 -> 250 | U12: =Forecast!U12 -> 250 | V12: =Forecast!V12 -> 250 | W12: =Forecast!W12 -> 250 | X12: =Forecast!X12 -> 250 | Y12: =Forecast!Y12 -> 200 | Z12: =Forecast!Z12 -> 200 | AA12: =Forecast!AA12 -> 200 | AB12: =SUM(P12:AA12) -> 2463 | AC12: =Forecast!AC12 -> 200 | AD12: =Forecast!AD12 -> 200 | AE12: =Forecast!AE12 -> 204 | AF12: =Forecast!AF12 -> 306 | AG12: =Forecast!AG12 -> 255 | AH12: =Forecast!AH12 -> 255 | AI12: =Forecast!AI12 -> 255 | AJ12: =Forecast!AJ12 -> 255 | ... AN12: =Forecast!AN12 -> 204 | AO12: =SUM(AC12:AN12) -> 2797 | AP12: =AB12/O12-1 -> 0.024116424
A13: 50g | B13: =Forecast!B13 -> Al Fakher Blueberry Mint 50g | C13: 0 | D13: 1 | E13: 0 | F13: 0 | G13: 0 | H13: 25 | I13: 3 | J13: 5 | K13: 20 | L13: 21 | M13: 0 | N13: 0 | O13: =SUM(C13:N13) -> 75 | P13: 0 | Q13: 0 | R13: 0 | S13: =Forecast!S13 -> 0 | T13: =Forecast!T13 -> 0 | U13: =Forecast!U13 -> 0 | V13: =Forecast!V13 -> 0 | W13: =Forecast!W13 -> 0 | X13: =Forecast!X13 -> 0 | Y13: =Forecast!Y13 -> 0 | Z13: =Forecast!Z13 -> 0 | AA13: =Forecast!AA13 -> 0 | AB13: =SUM(P13:AA13) -> 0 | AC13: =Forecast!AC13 -> 0 | AD13: =Forecast!AD13 -> 0 | AE13: =Forecast!AE13 -> 0 | AF13: =Forecast!AF13 -> 0 | AG13: =Forecast!AG13 -> 0 | AH13: =Forecast!AH13 -> 0 | AI13: =Forecast!AI13 -> 0 | AJ13: =Forecast!AJ13 -> 0 | ... AN13: =Forecast!AN13 -> 0 | AO13: =SUM(AC13:AN13) -> 0
A14: 50g | B14: =Forecast!B14 -> Al Fakher Blueberry 50g | C14: 0 | D14: 0 | E14: 5 | F14: 86 | G14: 5 | H14: 14 | I14: 60 | J14: 4 | K14: 74 | L14: 89 | M14: 0 | N14: 0 | O14: =SUM(C14:N14) -> 337 | P14: 13 | Q14: 23 | R14: 42 | S14: =Forecast!S14 -> 30 | T14: =Forecast!T14 -> 60 | U14: =Forecast!U14 -> 60 | V14: =Forecast!V14 -> 60 | W14: =Forecast!W14 -> 60 | X14: =Forecast!X14 -> 60 | Y14: =Forecast!Y14 -> 60 | Z14: =Forecast!Z14 -> 60 | AA14: =Forecast!AA14 -> 30 | AB14: =SUM(P14:AA14) -> 558 | AC14: =Forecast!AC14 -> 150 | AD14: =Forecast!AD14 -> 75 | AE14: =Forecast!AE14 -> 30.6 | AF14: =Forecast!AF14 -> 30.6 | AG14: =Forecast!AG14 -> 61.2 | AH14: =Forecast!AH14 -> 61.2 | AI14: =Forecast!AI14 -> 61.2 | AJ14: =Forecast!AJ14 -> 61.2 | ... AN14: =Forecast!AN14 -> 30.6 | AO14: =SUM(AC14:AN14) -> 745.2 | AP14: =AB14/O14-1 -> 0.65578635
A15: 50g | B15: =Forecast!B15 -> Al Fakher Buble Gum 50g | C15: 0 | D15: 1 | E15: 0 | F15: 1 | G15: 0 | H15: 1 | I15: 0 | J15: 0 | K15: 1 | L15: 24 | M15: 3 | N15: 0 | O15: =SUM(C15:N15) -> 31 | P15: 2 | Q15: 5 | R15: 0 | S15: =Forecast!S15 -> 0 | T15: =Forecast!T15 -> 0 | U15: =Forecast!U15 -> 0 | V15: =Forecast!V15 -> 0 | W15: =Forecast!W15 -> 0 | X15: =Forecast!X15 -> 0 | Y15: =Forecast!Y15 -> 0 | Z15: =Forecast!Z15 -> 0 | AA15: =Forecast!AA15 -> 0 | AB15: =SUM(P15:AA15) -> 7 | AC15: =Forecast!AC15 -> 0 | AD15: =Forecast!AD15 -> 0 | AE15: =Forecast!AE15 -> 0 | AF15: =Forecast!AF15 -> 0 | AG15: =Forecast!AG15 -> 0 | AH15: =Forecast!AH15 -> 0 | AI15: =Forecast!AI15 -> 0 | AJ15: =Forecast!AJ15 -> 0 | ... AN15: =Forecast!AN15 -> 0 | AO15: =SUM(AC15:AN15) -> 0
A16: 50g | B16: =Forecast!B16 -> Al Fakher Grapes & Mint 50g | C16: 224 | D16: 19 | E16: 241 | F16: 156 | G16: 106 | H16: 192 | I16: 188 | J16: 213 | K16: 390 | L16: 389 | M16: 210 | N16: 46 | O16: =SUM(C16:N16) -> 2374 | P16: 223 | Q16: 83 | R16: 67 | S16: =Forecast!S16 -> 243 | T16: =Forecast!T16 -> 139 | U16: =Forecast!U16 -> 270 | V16: =Forecast!V16 -> 270 | W16: =Forecast!W16 -> 270 | X16: =Forecast!X16 -> 250 | Y16: =Forecast!Y16 -> 250 | Z16: =Forecast!Z16 -> 200 | AA16: =Forecast!AA16 -> 200 | AB16: =SUM(P16:AA16) -> 2465 | AC16: =Forecast!AC16 -> 230 | AD16: =Forecast!AD16 -> 230 | AE16: =Forecast!AE16 -> 234.6 | AF16: =Forecast!AF16 -> 247.86 | AG16: =Forecast!AG16 -> 141.78 | AH16: =Forecast!AH16 -> 275.4 | AI16: =Forecast!AI16 -> 275.4 | AJ16: =Forecast!AJ16 -> 275.4 | ... AN16: =Forecast!AN16 -> 204 | AO16: =SUM(AC16:AN16) -> 2828.44 | AP16: =AB16/O16-1 -> 0.038331929
A17: 50g | B17: =Forecast!B17 -> Al Fakher Grapes 50g | C17: 248 | D17: 0 | E17: 800 | F17: 187 | G17: 0 | H17: 354 | I17: 540 | J17: 313 | K17: 256 | L17: 457 | M17: 273 | N17: 58 | O17: =SUM(C17:N17) -> 3486 | P17: 343 | Q17: 90 | R17: 136 | S17: =Forecast!S17 -> 450 | T17: =Forecast!T17 -> 450 | U17: =Forecast!U17 -> 450 | V17: =Forecast!V17 -> 400 | W17: =Forecast!W17 -> 400 | X17: =Forecast!X17 -> 400 | Y17: =Forecast!Y17 -> 350 | Z17: =Forecast!Z17 -> 300 | AA17: =Forecast!AA17 -> 250 | AB17: =SUM(P17:AA17) -> 4019 | AC17: =Forecast!AC17 -> 400 | AD17: =Forecast!AD17 -> 400 | AE17: =Forecast!AE17 -> 367.2 | AF17: =Forecast!AF17 -> 459 | AG17: =Forecast!AG17 -> 459 | AH17: =Forecast!AH17 -> 459 | AI17: =Forecast!AI17 -> 408 | AJ17: =Forecast!AJ17 -> 408 | ... AN17: =Forecast!AN17 -> 255 | AO17: =SUM(AC17:AN17) -> 4686.2 | AP17: =AB17/O17-1 -> 0.1528973
A18: 50g | B18: =Forecast!B18 -> Al Fakher Gum Mint 50g | C18: 0 | D18: 0 | E18: 133 | F18: 97 | G18: 60 | H18: 54 | I18: 0 | J18: 0 | K18: 223 | L18: 0 | M18: 136 | N18: 4 | O18: =SUM(C18:N18) -> 707 | P18: 160 | Q18: 21 | R18: 21 | S18: =Forecast!S18 -> 75 | T18: =Forecast!T18 -> 100 | U18: =Forecast!U18 -> 100 | V18: =Forecast!V18 -> 100 | W18: =Forecast!W18 -> 100 | X18: =Forecast!X18 -> 75 | Y18: =Forecast!Y18 -> 75 | Z18: =Forecast!Z18 -> 75 | AA18: =Forecast!AA18 -> 75 | AB18: =SUM(P18:AA18) -> 977 | AC18: =Forecast!AC18 -> 200 | AD18: =Forecast!AD18 -> 150 | AE18: =Forecast!AE18 -> 25.5 | AF18: =Forecast!AF18 -> 76.5 | AG18: =Forecast!AG18 -> 102 | AH18: =Forecast!AH18 -> 102 | AI18: =Forecast!AI18 -> 102 | AJ18: =Forecast!AJ18 -> 102 | ... AN18: =Forecast!AN18 -> 76.5 | AO18: =SUM(AC18:AN18) -> 1166 | AP18: =AB18/O18-1 -> 0.38189533
A19: 50g | B19: =Forecast!B19 -> Al Fakher Gum 50g | C19: 20 | D19: 11 | E19: 1 | F19: 13 | G19: 6 | H19: 17 | I19: 33 | J19: 1 | K19: 28 | L19: 74 | M19: 44 | N19: 4 | O19: =SUM(C19:N19) -> 252 | P19: 50 | Q19: 2 | R19: 6 | S19: =Forecast!S19 -> 50 | T19: =Forecast!T19 -> 50 | U19: =Forecast!U19 -> 40 | V19: =Forecast!V19 -> 40 | W19: =Forecast!W19 -> 40 | X19: =Forecast!X19 -> 40 | Y19: =Forecast!Y19 -> 30 | Z19: =Forecast!Z19 -> 30 | AA19: =Forecast!AA19 -> 20 | AB19: =SUM(P19:AA19) -> 398 | AC19: =Forecast!AC19 -> 20 | AD19: =Forecast!AD19 -> 20 | AE19: =Forecast!AE19 -> 7.14 | AF19: =Forecast!AF19 -> 51 | AG19: =Forecast!AG19 -> 51 | AH19: =Forecast!AH19 -> 40.8 | AI19: =Forecast!AI19 -> 40.8 | AJ19: =Forecast!AJ19 -> 40.8 | ... AN19: =Forecast!AN19 -> 20.4 | AO19: =SUM(AC19:AN19) -> 393.94 | AP19: =AB19/O19-1 -> 0.57936508
A20: 50g | B20: =Forecast!B20 -> Al Fakher Lemon Mint 50g | C20: 390 | D20: 11 | E20: 143 | F20: 292 | G20: 213 | H20: 104 | I20: 422 | J20: 147 | K20: 214 | L20: 505 | M20: 246 | N20: 62 | O20: =SUM(C20:N20) -> 2749 | P20: 286 | Q20: 88 | R20: 178 | S20: =Forecast!S20 -> 300 | T20: =Forecast!T20 -> 400 | U20: =Forecast!U20 -> 400 | V20: =Forecast!V20 -> 350 | W20: =Forecast!W20 -> 350 | X20: =Forecast!X20 -> 350 | Y20: =Forecast!Y20 -> 250 | Z20: =Forecast!Z20 -> 250 | AA20: =Forecast!AA20 -> 250 | AB20: =SUM(P20:AA20) -> 3452 | AC20: =Forecast!AC20 -> 250 | AD20: =Forecast!AD20 -> 250 | AE20: =Forecast!AE20 -> 153 | AF20: =Forecast!AF20 -> 306 | AG20: =Forecast!AG20 -> 408 | AH20: =Forecast!AH20 -> 408 | AI20: =Forecast!AI20 -> 357 | AJ20: =Forecast!AJ20 -> 357 | ... AN20: =Forecast!AN20 -> 255 | AO20: =SUM(AC20:AN20) -> 3611 | AP20: =AB20/O20-1 -> 0.25572936
A21: 50g | B21: =Forecast!B21 -> Al Fakher Magic Love 50g | C21: 17 | D21: 1 | E21: 9 | F21: 28 | G21: 16 | H21: 72 | I21: 116 | J21: 96 | K21: 103 | L21: 223 | M21: 47 | N21: 2 | O21: =SUM(C21:N21) -> 730 | P21: 54 | Q21: 8 | R21: 43 | S21: =Forecast!S21 -> 50 | T21: =Forecast!T21 -> 40 | U21: =Forecast!U21 -> 80 | V21: =Forecast!V21 -> 80 | W21: =Forecast!W21 -> 80 | X21: =Forecast!X21 -> 75 | Y21: =Forecast!Y21 -> 75 | Z21: =Forecast!Z21 -> 50 | AA21: =Forecast!AA21 -> 50 | AB21: =SUM(P21:AA21) -> 685 | AC21: =Forecast!AC21 -> 30 | AD21: =Forecast!AD21 -> 30 | AE21: =Forecast!AE21 -> 71.4 | AF21: =Forecast!AF21 -> 51 | AG21: =Forecast!AG21 -> 40.8 | AH21: =Forecast!AH21 -> 81.6 | AI21: =Forecast!AI21 -> 81.6 | AJ21: =Forecast!AJ21 -> 81.6 | ... AN21: =Forecast!AN21 -> 51 | AO21: =SUM(AC21:AN21) -> 723 | AP21: =AB21/O21-1 -> -0.061643836
A22: 50g | B22: =Forecast!B22 -> Al Fakher Mint 50g | C22: 0 | D22: 0 | E22: 845 | F22: 401 | G22: 190 | H22: 199 | I22: 450 | J22: 235 | K22: 299 | L22: 498 | M22: 391 | N22: 26 | O22: =SUM(C22:N22) -> 3534 | P22: 339 | Q22: 94 | R22: 113 | S22: =Forecast!S22 -> 400 | T22: =Forecast!T22 -> 400 | U22: =Forecast!U22 -> 400 | V22: =Forecast!V22 -> 400 | W22: =Forecast!W22 -> 400 | X22: =Forecast!X22 -> 400 | Y22: =Forecast!Y22 -> 300 | Z22: =Forecast!Z22 -> 300 | AA22: =Forecast!AA22 -> 200 | AB22: =SUM(P22:AA22) -> 3746 | AC22: =Forecast!AC22 -> 400 | AD22: =Forecast!AD22 -> 300 | AE22: =Forecast!AE22 -> 306 | AF22: =Forecast!AF22 -> 408 | AG22: =Forecast!AG22 -> 408 | AH22: =Forecast!AH22 -> 408 | AI22: =Forecast!AI22 -> 408 | AJ22: =Forecast!AJ22 -> 408 | ... AN22: =Forecast!AN22 -> 204 | AO22: =SUM(AC22:AN22) -> 4270 | AP22: =AB22/O22-1 -> 0.059988681
A23: 50g | B23: =Forecast!B23 -> Al Fakher Two apple 50g | C23: 8790 | D23: 1109 | E23: 8523 | F23: 8187 | G23: 4 | H23: 5001 | I23: 6654 | J23: 3946 | K23: 9735 | L23: 3845 | M23: 10560 | N23: 6450 | O23: =SUM(C23:N23) -> 72804 | P23: 8307 | Q23: 4286 | R23: 6641 | S23: =Forecast!S23 -> 7500 | T23: =Forecast!T23 -> 6500 | U23: =Forecast!U23 -> 6500 | V23: =Forecast!V23 -> 7000 | W23: =Forecast!W23 -> 7000 | X23: =Forecast!X23 -> 6500 | Y23: =Forecast!Y23 -> 6500 | Z23: =Forecast!Z23 -> 6000 | AA23: =Forecast!AA23 -> 4500 | AB23: =SUM(P23:AA23) -> 77234 | AC23: =Forecast!AC23 -> 7500 | AD23: =Forecast!AD23 -> 8000 | AE23: =Forecast!AE23 -> 9180 | AF23: =Forecast!AF23 -> 7650 | AG23: =Forecast!AG23 -> 6630 | AH23: =Forecast!AH23 -> 6630 | AI23: =Forecast!AI23 -> 7140 | AJ23: =Forecast!AJ23 -> 7140 | ... AN23: =Forecast!AN23 -> 4590 | AO23: =SUM(AC23:AN23) -> 83840 | AP23: =AB23/O23-1 -> 0.060848305
A24: 50g | B24: =Forecast!B24 -> Lemonade Mint 50g | K24: 1432 | L24: 0 | M24: =Forecast!M24 -> 0 | N24: =Forecast!N24 -> 0 | O24: =SUM(C24:N24) -> 1432 | P24: =Forecast!P24 -> 0 | Q24: =Forecast!Q24 -> 0 | R24: =Forecast!R24 -> 0 | S24: =Forecast!S24 -> 0 | T24: =Forecast!T24 -> 0 | U24: =Forecast!U24 -> 0 | V24: =Forecast!V24 -> 0 | W24: =Forecast!W24 -> 0 | ... AA24: =Forecast!AA24 -> 0 | AB24: =SUM(P24:AA24) -> 0 | AC24: =Forecast!AC24 -> 0 | AD24: =Forecast!AD24 -> 0 | AE24: =Forecast!AE24 -> 0 | AF24: =Forecast!AF24 -> 0 | AG24: =Forecast!AG24 -> 0 | AH24: =Forecast!AH24 -> 0 | AI24: =Forecast!AI24 -> 0 | AJ24: =Forecast!AJ24 -> 0 | ... AN24: =Forecast!AN24 -> 0 | AO24: =SUM(AC24:AN24) -> 0
A25: 50g | B25: =Forecast!B25 -> Lemonade Pear 50g | K25: 1477 | L25: 0 | M25: =Forecast!M25 -> 0 | N25: =Forecast!N25 -> 0 | O25: =SUM(C25:N25) -> 1477 | P25: =Forecast!P25 -> 0 | Q25: =Forecast!Q25 -> 0 | R25: =Forecast!R25 -> 0 | S25: =Forecast!S25 -> 0 | T25: =Forecast!T25 -> 0 | U25: =Forecast!U25 -> 0 | V25: =Forecast!V25 -> 0 | W25: =Forecast!W25 -> 0 | ... AA25: =Forecast!AA25 -> 0 | AB25: =SUM(P25:AA25) -> 0 | AC25: =Forecast!AC25 -> 0 | AD25: =Forecast!AD25 -> 0 | AE25: =Forecast!AE25 -> 0 | AF25: =Forecast!AF25 -> 0 | AG25: =Forecast!AG25 -> 0 | AH25: =Forecast!AH25 -> 0 | AI25: =Forecast!AI25 -> 0 | AJ25: =Forecast!AJ25 -> 0 | ... AN25: =Forecast!AN25 -> 0 | AO25: =SUM(AC25:AN25) -> 0
A26: 50g | B26: Al Fakher Double Apple Classic 50g | O26: =SUM(C26:N26) -> 0 | P26: =Forecast!P26 -> 0 | Q26: =Forecast!Q26 -> 0 | R26: =Forecast!R26 -> 0 | S26: =Forecast!S26 -> 0 | T26: =Forecast!T26 -> 0 | U26: =Forecast!U26 -> 0 | V26: =Forecast!V26 -> 0 | W26: =Forecast!W26 -> 0 | ... AA26: =Forecast!AA26 -> 0 | AB26: =SUM(P26:AA26) -> 0 | AC26: =Forecast!AC26 -> 0 | AD26: =Forecast!AD26 -> 0 | AE26: =Forecast!AE26 -> 0 | AF26: =Forecast!AF26 -> 0 | AG26: =Forecast!AG26 -> 0 | AH26: =Forecast!AH26 -> 0 | AI26: =Forecast!AI26 -> 0 | AJ26: =Forecast!AJ26 -> 0 | ... AN26: =Forecast!AN26 -> 0 | AO26: =SUM(AC26:AN26) -> 0
A27: 250g | B27: Al Fakher Double Apple Classic 250g | O27: =SUM(C27:N27) -> 0 | P27: =Forecast!P27 -> 0 | Q27: =Forecast!Q27 -> 0 | R27: =Forecast!R27 -> 0 | S27: =Forecast!S27 -> 0 | T27: =Forecast!T27 -> 0 | U27: =Forecast!U27 -> 0 | V27: =Forecast!V27 -> 0 | W27: =Forecast!W27 -> 0 | ... AA27: =Forecast!AA27 -> 0 | AB27: =SUM(P27:AA27) -> 0 | AC27: =Forecast!AC27 -> 0 | AD27: =Forecast!AD27 -> 0 | AE27: =Forecast!AE27 -> 0 | AF27: =Forecast!AF27 -> 0 | AG27: =Forecast!AG27 -> 0 | AH27: =Forecast!AH27 -> 0 | AI27: =Forecast!AI27 -> 0 | AJ27: =Forecast!AJ27 -> 0 | ... AN27: =Forecast!AN27 -> 0 | AO27: =SUM(AC27:AN27) -> 0
A28: 1kg | B28: Al Fakher Double Apple Classic 1Kg | O28: =SUM(C28:N28) -> 0 | P28: =Forecast!P28 -> 0 | Q28: =Forecast!Q28 -> 0 | R28: =Forecast!R28 -> 0 | S28: =Forecast!S28 -> 0 | T28: =Forecast!T28 -> 0 | U28: =Forecast!U28 -> 0 | V28: =Forecast!V28 -> 0 | W28: =Forecast!W28 -> 0 | ... AA28: =Forecast!AA28 -> 300 | AB28: =SUM(P28:AA28) -> 900 | AC28: =Forecast!AC28 -> 300 | AD28: =Forecast!AD28 -> 300 | AE28: =Forecast!AE28 -> 300 | AF28: =Forecast!AF28 -> 300 | AG28: =Forecast!AG28 -> 300 | AH28: =Forecast!AH28 -> 300 | AI28: =Forecast!AI28 -> 300 | AJ28: =Forecast!AJ28 -> 300 | ... AN28: =Forecast!AN28 -> 300 | AO28: =SUM(AC28:AN28) -> 3600
A29: 50g | B29: Al Fakher Italian Lemon Mint 50g | O29: =SUM(C29:N29) -> 0 | P29: =Forecast!P29 -> 0 | Q29: =Forecast!Q29 -> 0 | R29: =Forecast!R29 -> 0 | S29: =Forecast!S29 -> 0 | T29: =Forecast!T29 -> 0 | U29: =Forecast!U29 -> 0 | V29: =Forecast!V29 -> 0 | W29: =Forecast!W29 -> 0 | ... AA29: =Forecast!AA29 -> 250 | AB29: =SUM(P29:AA29) -> 750 | AC29: =Forecast!AC29 -> 350 | AD29: =Forecast!AD29 -> 250 | AE29: =Forecast!AE29 -> 262.5 | AF29: =Forecast!AF29 -> 275.625 | AG29: =Forecast!AG29 -> 289.40625 | AH29: =Forecast!AH29 -> 303.87656 | AI29: =Forecast!AI29 -> 319.07039 | AJ29: =Forecast!AJ29 -> 335.02391 | ... AN29: =Forecast!AN29 -> 250 | AO29: =SUM(AC29:AN29) -> 3487.2772
A30: 250g | B30: Al Fakher Italian Lemon Mint 250g | O30: =SUM(C30:N30) -> 0 | P30: =Forecast!P30 -> 0 | Q30: =Forecast!Q30 -> 0 | R30: =Forecast!R30 -> 0 | S30: =Forecast!S30 -> 0 | T30: =Forecast!T30 -> 0 | U30: =Forecast!U30 -> 0 | V30: =Forecast!V30 -> 0 | W30: =Forecast!W30 -> 0 | ... AA30: =Forecast!AA30 -> 150 | AB30: =SUM(P30:AA30) -> 450 | AC30: =Forecast!AC30 -> 200 | AD30: =Forecast!AD30 -> 200 | AE30: =Forecast!AE30 -> 210 | AF30: =Forecast!AF30 -> 220.5 | AG30: =Forecast!AG30 -> 231.525 | AH30: =Forecast!AH30 -> 243.10125 | AI30: =Forecast!AI30 -> 255.25631 | AJ30: =Forecast!AJ30 -> 268.01913 | ... AN30: =Forecast!AN30 -> 200 | AO30: =SUM(AC30:AN30) -> 2709.8218
A31: 1kg | B31: Al Fakher Italian Lemon Mint 1Kg | O31: =SUM(C31:N31) -> 0 | P31: =Forecast!P31 -> 0 | Q31: =Forecast!Q31 -> 0 | R31: =Forecast!R31 -> 0 | S31: =Forecast!S31 -> 0 | T31: =Forecast!T31 -> 0 | U31: =Forecast!U31 -> 0 | V31: =Forecast!V31 -> 0 | W31: =Forecast!W31 -> 0 | ... AA31: =Forecast!AA31 -> 200 | AB31: =SUM(P31:AA31) -> 600 | AC31: =Forecast!AC31 -> 250 | AD31: =Forecast!AD31 -> 200 | AE31: =Forecast!AE31 -> 210 | AF31: =Forecast!AF31 -> 220.5 | AG31: =Forecast!AG31 -> 231.525 | AH31: =Forecast!AH31 -> 243.10125 | AI31: =Forecast!AI31 -> 255.25631 | AJ31: =Forecast!AJ31 -> 268.01913 | ... AN31: =Forecast!AN31 -> 200 | AO31: =SUM(AC31:AN31) -> 2759.8218
B32: Total without Classic & Italian | C32: =SUM(C3:C31) -> 14784 | D32: =SUM(D3:D31) -> 10218 | E32: =SUM(E3:E31) -> 21235 | F32: =SUM(F3:F31) -> 22196 | G32: =SUM(G3:G31) -> 1554 | H32: =SUM(H3:H31) -> 10767 | I32: =SUM(I3:I31) -> 14935 | J32: =SUM(J3:J31) -> 17847 | ... O32: =SUM(O3:O31) -> 196991 | P32: =SUM(P3:P23) -> 21751 | Q32: =SUM(Q3:Q23) -> 12477 | R32: =SUM(R3:R23) -> 17693 | S32: =SUM(S3:S23) -> 21123 | T32: =SUM(T3:T23) -> 20164 | U32: =SUM(U3:U23) -> 20350 | V32: =SUM(V3:V23) -> 21725 | W32: =SUM(W3:W23) -> 21225 | ... AO32: =SUM(AO3:AO23) -> 239510.38
B34: Total with Classic & Italian | C34: =SUM(C3:C31) -> 14784 | D34: =SUM(D3:D31) -> 10218 | E34: =SUM(E3:E31) -> 21235 | F34: =SUM(F3:F31) -> 22196 | G34: =SUM(G3:G31) -> 1554 | H34: =SUM(H3:H31) -> 10767 | I34: =SUM(I3:I31) -> 14935 | J34: =SUM(J3:J31) -> 17847 | ... AO34: =SUM(AO3:AO31) -> 252067.3
C35: =C32*6 -> 88704 | D35: =D32*6 -> 61308 | E35: =E32*6 -> 127410 | F35: =F32*6 -> 133176 | G35: =G32*6 -> 9324 | H35: =H32*6 -> 64602 | I35: =I32*6 -> 89610 | J35: =J32*6 -> 107082 | ... N35: =N32*6 -> 71328 | P35: =P32*6 -> 130506 | Q35: =Q32*6 -> 74862 | R35: =R32*6 -> 106158 | S35: =S32*6 -> 126738 | T35: =T32*6 -> 120984 | U35: =U32*6 -> 122100 | V35: =V32*6 -> 130350 | W35: =W32*6 -> 127350 | ... AA35: =AA32*6 -> 80730 | AC35: =AC32*6 -> 128580 | AD35: =AD32*6 -> 126900 | AE35: =AE32*6 -> 129266.64 | AF35: =AF32*6 -> 129272.76 | AG35: =AG32*6 -> 123403.68 | AH35: =AH32*6 -> 124542 | AI35: =AI32*6 -> 132957 | AJ35: =AJ32*6 -> 129897 | ... AN35: =AN32*6 -> 82344.6

Sheet IMS +ve Sens
A2: SKU Name | B2: 45658 | C2: 45689 | D2: 45717 | E2: 45748 | F2: 45778 | G2: 45809 | H2: 45839 | I2: 45870 | J2: 45901 | K2: 45931 | L2: 45962 | M2: 45992 | N2: Total 2025 | O2: 46023 | P2: 46054 | Q2: 46082 | R2: 46113 | S2: 46143 | T2: 46174 | U2: 46204 | V2: 46235 | W2: 46266 | X2: 46296 | Y2: 46327 | Z2: 46357 | AA2: Total 2026
A3: Al Fakher Grapes & Mint 1kg | O3: 250 | P3: 250 | Q3: 250 | R3: 280 | S3: 300 | T3: 300 | U3: 300 | V3: 300 | W3: 250 | X3: 250 | Y3: 250 | Z3: 250 | AA3: =SUM(O3:Z3) -> 3230
A4: Al Fakher Grapes 1kg | O4: 800 | P4: 800 | Q4: 800 | R4: 1000 | S4: 1000 | T4: 1000 | U4: 1000 | V4: 1000 | W4: 750 | X4: 700 | Y4: 700 | Z4: 700 | AA4: =SUM(O4:Z4) -> 10250
A5: Al Fakher Lemon Mint 1kg | O5: 500 | P5: 500 | Q5: 500 | R5: 500 | S5: 600 | T5: 600 | U5: 600 | V5: 500 | W5: 300 | X5: 300 | Y5: 300 | Z5: 300 | AA5: =SUM(O5:Z5) -> 5500
A6: Al Fakher Mint 1kg | O6: 550 | P6: 550 | Q6: 550 | R6: 600 | S6: 600 | T6: 600 | U6: 600 | V6: 600 | W6: 500 | X6: 500 | Y6: 500 | Z6: 500 | AA6: =SUM(O6:Z6) -> 6650
A7: Al Fakher Two apple 1kg | O7: 4000 | P7: 3500 | Q7: 3500 | R7: 4000 | S7: 4000 | T7: 4000 | U7: 4000 | V7: 4000 | W7: 4000 | X7: 2500 | Y7: 2500 | Z7: 2200 | AA7: =SUM(O7:Z7) -> 42200
A8: Al Fakher Grapes & Mint 250g | O8: 125 | P8: 125 | Q8: 125 | R8: 150 | S8: 150 | T8: 150 | U8: 200 | V8: 200 | W8: 150 | X8: 125 | Y8: 125 | Z8: 125 | AA8: =SUM(O8:Z8) -> 1750
A9: Al Fakher Grapes 250g | O9: 250 | P9: 250 | Q9: 250 | R9: 300 | S9: 350 | T9: 350 | U9: 300 | V9: 300 | W9: 250 | X9: 200 | Y9: 200 | Z9: 200 | AA9: =SUM(O9:Z9) -> 3200
A10: Al Fakher Lemon Mint 250g | O10: 175 | P10: 200 | Q10: 200 | R10: 200 | S10: 200 | T10: 200 | U10: 200 | V10: 175 | W10: 175 | X10: 150 | Y10: 150 | Z10: 150 | AA10: =SUM(O10:Z10) -> 2175
A11: Al Fakher Two apple 250g | O11: 4500 | P11: 4500 | Q11: 4500 | R11: 4500 | S11: 5000 | T11: 5000 | U11: 5000 | V11: 5000 | W11: 4500 | X11: 4500 | Y11: 4500 | Z11: 4500 | AA11: =SUM(O11:Z11) -> 56000
A12: Al Fakher Two Apple Bahraini 250g | O12: 300 | P12: 300 | Q12: 250 | R12: 300 | S12: 300 | T12: 300 | U12: 300 | V12: 300 | W12: 300 | X12: 300 | Y12: 250 | Z12: 250 | AA12: =SUM(O12:Z12) -> 3450
A13: Al Fakher Blueberry Mint 50g | O13: 0 | P13: 0 | Q13: 0 | R13: 0 | S13: 0 | T13: 0 | U13: 0 | V13: 0 | W13: 0 | X13: 0 | Y13: 0 | Z13: 0 | AA13: =SUM(O13:Z13) -> 0
A14: Al Fakher Blueberry 50g | O14: 60 | P14: 60 | Q14: 60 | R14: 60 | S14: 60 | T14: 60 | U14: 60 | V14: 60 | W14: 30 | X14: 30 | Y14: 30 | Z14: 30 | AA14: =SUM(O14:Z14) -> 600
... A23: Al Fakher Two apple 50g | O23: 8000 | P23: 7000 | Q23: 6000 | R23: 7000 | S23: 7500 | T23: 7500 | U23: 7500 | V23: 7500 | W23: 6000 | X23: 5500 | Y23: 5500 | Z23: 5000 | AA23: =SUM(O23:Z23) -> 80000
A24: =Forecast!B24 -> Lemonade Mint 50g
A25: =Forecast!B25 -> Lemonade Pear 50g
A26: =Forecast!B26 -> Al Fakher Double Apple Classic 50g | AA26: =SUM(O26:Z26) -> 0
A27: =Forecast!B27 -> Al Fakher Double Apple Classic 250g | AA27: =SUM(O27:Z27) -> 0
A28: =Forecast!B28 -> Al Fakher Double Apple Classic 1Kg | AA28: =SUM(O28:Z28) -> 0
A29: =Forecast!B29 -> Al Fakher Italian Lemon Mint 50g | AA29: =SUM(O29:Z29) -> 0
A30: =Forecast!B30 -> Al Fakher Italian Lemon Mint 250g | AA30: =SUM(O30:Z30) -> 0
A31: =Forecast!B31 -> Al Fakher Italian Lemon Mint 1Kg | AA31: =SUM(O31:Z31) -> 0
O32: =SUM(O3:O31) -> 21060 | P32: =SUM(P3:P31) -> 19435 | Q32: =SUM(Q3:Q31) -> 18435 | R32: =SUM(R3:R31) -> 20530 | S32: =SUM(S3:S31) -> 21850 | T32: =SUM(T3:T31) -> 21880 | U32: =SUM(U3:U31) -> 21850 | V32: =SUM(V3:V31) -> 21625 | ... Z32: =SUM(Z3:Z31) -> 15355 | AA32: =SUM(AA3:AA23) -> 233095
O33: 20600 | P33: 20430 | Q33: 19070 | R33: 18640 | S33: 18820 | T33: 18520 | U33: 18295 | V33: 17745 | W33: 16425 | X33: 12415 | Y33: 12340 | Z33: 11790
O34: =O32-O33 -> 460 | P34: =P32-P33 -> -995 | Q34: =Q32-Q33 -> -635 | R34: =R32-R33 -> 1890 | S34: =S32-S33 -> 3030 | T34: =T32-T33 -> 3360 | U34: =U32-U33 -> 3555 | V34: =V32-V33 -> 3880 | ... Z34: =Z32-Z33 -> 3565

Sheet IMS -ve Sens
A2: SKU Name | B2: 45658 | C2: 45689 | D2: 45717 | E2: 45748 | F2: 45778 | G2: 45809 | H2: 45839 | I2: 45870 | J2: 45901 | K2: 45931 | L2: 45962 | M2: 45992 | N2: Total 2025 | O2: 46023 | P2: 46054 | Q2: 46082 | R2: 46113 | S2: 46143 | T2: 46174 | U2: 46204 | V2: 46235 | W2: 46266 | X2: 46296 | Y2: 46327 | Z2: 46357 | AA2: Total 2026
A3: Al Fakher Grapes & Mint 1kg | O3: ='IMS +ve Sens'!O3-('IMS +ve Sens'!O3*12%) -> 220 | P3: ='IMS +ve Sens'!P3-('IMS +ve Sens'!P3*12%) -> 220 | Q3: ='IMS +ve Sens'!Q3-('IMS +ve Sens'!Q3*12%) -> 220 | R3: ='IMS +ve Sens'!R3-('IMS +ve Sens'!R3*12%) -> 246.4 | S3: ='IMS +ve Sens'!S3-('IMS +ve Sens'!S3*12%) -> 264 | T3: ='IMS +ve Sens'!T3-('IMS +ve Sens'!T3*12%) -> 264 | U3: ='IMS +ve Sens'!U3-('IMS +ve Sens'!U3*12%) -> 264 | V3: ='IMS +ve Sens'!V3-('IMS +ve Sens'!V3*12%) -> 264 | ... Z3: ='IMS +ve Sens'!Z3-('IMS +ve Sens'!Z3*12%) -> 220 | AA3: =SUM(O3:Z3) -> 2842.4
A4: Al Fakher Grapes 1kg | O4: ='IMS +ve Sens'!O4-('IMS +ve Sens'!O4*12%) -> 704 | P4: ='IMS +ve Sens'!P4-('IMS +ve Sens'!P4*12%) -> 704 | Q4: ='IMS +ve Sens'!Q4-('IMS +ve Sens'!Q4*12%) -> 704 | R4: ='IMS +ve Sens'!R4-('IMS +ve Sens'!R4*12%) -> 880 | S4: ='IMS +ve Sens'!S4-('IMS +ve Sens'!S4*12%) -> 880 | T4: ='IMS +ve Sens'!T4-('IMS +ve Sens'!T4*12%) -> 880 | U4: ='IMS +ve Sens'!U4-('IMS +ve Sens'!U4*12%) -> 880 | V4: ='IMS +ve Sens'!V4-('IMS +ve Sens'!V4*12%) -> 880 | ... Z4: ='IMS +ve Sens'!Z4-('IMS +ve Sens'!Z4*12%) -> 616 | AA4: =SUM(O4:Z4) -> 9020
A5: Al Fakher Lemon Mint 1kg | O5: ='IMS +ve Sens'!O5-('IMS +ve Sens'!O5*12%) -> 440 | P5: ='IMS +ve Sens'!P5-('IMS +ve Sens'!P5*12%) -> 440 | Q5: ='IMS +ve Sens'!Q5-('IMS +ve Sens'!Q5*12%) -> 440 | R5: ='IMS +ve Sens'!R5-('IMS +ve Sens'!R5*12%) -> 440 | S5: ='IMS +ve Sens'!S5-('IMS +ve Sens'!S5*12%) -> 528 | T5: ='IMS +ve Sens'!T5-('IMS +ve Sens'!T5*12%) -> 528 | U5: ='IMS +ve Sens'!U5-('IMS +ve Sens'!U5*12%) -> 528 | V5: ='IMS +ve Sens'!V5-('IMS +ve Sens'!V5*12%) -> 440 | ... Z5: ='IMS +ve Sens'!Z5-('IMS +ve Sens'!Z5*12%) -> 264 | AA5: =SUM(O5:Z5) -> 4840
A6: Al Fakher Mint 1kg | O6: ='IMS +ve Sens'!O6-('IMS +ve Sens'!O6*12%) -> 484 | P6: ='IMS +ve Sens'!P6-('IMS +ve Sens'!P6*12%) -> 484 | Q6: ='IMS +ve Sens'!Q6-('IMS +ve Sens'!Q6*12%) -> 484 | R6: ='IMS +ve Sens'!R6-('IMS +ve Sens'!R6*12%) -> 528 | S6: ='IMS +ve Sens'!S6-('IMS +ve Sens'!S6*12%) -> 528 | T6: ='IMS +ve Sens'!T6-('IMS +ve Sens'!T6*12%) -> 528 | U6: ='IMS +ve Sens'!U6-('IMS +ve Sens'!U6*12%) -> 528 | V6: ='IMS +ve Sens'!V6-('IMS +ve Sens'!V6*12%) -> 528 | ... Z6: ='IMS +ve Sens'!Z6-('IMS +ve Sens'!Z6*12%) -> 440 | AA6: =SUM(O6:Z6) -> 5852
A7: Al Fakher Two apple 1kg | O7: ='IMS +ve Sens'!O7-('IMS +ve Sens'!O7*12%) -> 3520 | P7: ='IMS +ve Sens'!P7-('IMS +ve Sens'!P7*12%) -> 3080 | Q7: ='IMS +ve Sens'!Q7-('IMS +ve Sens'!Q7*12%) -> 3080 | R7: ='IMS +ve Sens'!R7-('IMS +ve Sens'!R7*12%) -> 3520 | S7: ='IMS +ve Sens'!S7-('IMS +ve Sens'!S7*12%) -> 3520 | T7: ='IMS +ve Sens'!T7-('IMS +ve Sens'!T7*12%) -> 3520 | U7: ='IMS +ve Sens'!U7-('IMS +ve Sens'!U7*12%) -> 3520 | V7: ='IMS +ve Sens'!V7-('IMS +ve Sens'!V7*12%) -> 3520 | ... Z7: ='IMS +ve Sens'!Z7-('IMS +ve Sens'!Z7*12%) -> 1936 | AA7: =SUM(O7:Z7) -> 37136
A8: Al Fakher Grapes & Mint 250g | O8: ='IMS +ve Sens'!O8-('IMS +ve Sens'!O8*12%) -> 110 | P8: ='IMS +ve Sens'!P8-('IMS +ve Sens'!P8*12%) -> 110 | Q8: ='IMS +ve Sens'!Q8-('IMS +ve Sens'!Q8*12%) -> 110 | R8: ='IMS +ve Sens'!R8-('IMS +ve Sens'!R8*12%) -> 132 | S8: ='IMS +ve Sens'!S8-('IMS +ve Sens'!S8*12%) -> 132 | T8: ='IMS +ve Sens'!T8-('IMS +ve Sens'!T8*12%) -> 132 | U8: ='IMS +ve Sens'!U8-('IMS +ve Sens'!U8*12%) -> 176 | V8: ='IMS +ve Sens'!V8-('IMS +ve Sens'!V8*12%) -> 176 | ... Z8: ='IMS +ve Sens'!Z8-('IMS +ve Sens'!Z8*12%) -> 110 | AA8: =SUM(O8:Z8) -> 1540
A9: Al Fakher Grapes 250g | O9: ='IMS +ve Sens'!O9-('IMS +ve Sens'!O9*12%) -> 220 | P9: ='IMS +ve Sens'!P9-('IMS +ve Sens'!P9*12%) -> 220 | Q9: ='IMS +ve Sens'!Q9-('IMS +ve Sens'!Q9*12%) -> 220 | R9: ='IMS +ve Sens'!R9-('IMS +ve Sens'!R9*12%) -> 264 | S9: ='IMS +ve Sens'!S9-('IMS +ve Sens'!S9*12%) -> 308 | T9: ='IMS +ve Sens'!T9-('IMS +ve Sens'!T9*12%) -> 308 | U9: ='IMS +ve Sens'!U9-('IMS +ve Sens'!U9*12%) -> 264 | V9: ='IMS +ve Sens'!V9-('IMS +ve Sens'!V9*12%) -> 264 | ... Z9: ='IMS +ve Sens'!Z9-('IMS +ve Sens'!Z9*12%) -> 176 | AA9: =SUM(O9:Z9) -> 2816
A10: Al Fakher Lemon Mint 250g | O10: ='IMS +ve Sens'!O10-('IMS +ve Sens'!O10*12%) -> 154 | P10: ='IMS +ve Sens'!P10-('IMS +ve Sens'!P10*12%) -> 176 | Q10: ='IMS +ve Sens'!Q10-('IMS +ve Sens'!Q10*12%) -> 176 | R10: ='IMS +ve Sens'!R10-('IMS +ve Sens'!R10*12%) -> 176 | S10: ='IMS +ve Sens'!S10-('IMS +ve Sens'!S10*12%) -> 176 | T10: ='IMS +ve Sens'!T10-('IMS +ve Sens'!T10*12%) -> 176 | U10: ='IMS +ve Sens'!U10-('IMS +ve Sens'!U10*12%) -> 176 | V10: ='IMS +ve Sens'!V10-('IMS +ve Sens'!V10*12%) -> 154 | ... Z10: ='IMS +ve Sens'!Z10-('IMS +ve Sens'!Z10*12%) -> 132 | AA10: =SUM(O10:Z10) -> 1914
A11: Al Fakher Two apple 250g | O11: ='IMS +ve Sens'!O11-('IMS +ve Sens'!O11*12%) -> 3960 | P11: ='IMS +ve Sens'!P11-('IMS +ve Sens'!P11*12%) -> 3960 | Q11: ='IMS +ve Sens'!Q11-('IMS +ve Sens'!Q11*12%) -> 3960 | R11: ='IMS +ve Sens'!R11-('IMS +ve Sens'!R11*12%) -> 3960 | S11: ='IMS +ve Sens'!S11-('IMS +ve Sens'!S11*12%) -> 4400 | T11: ='IMS +ve Sens'!T11-('IMS +ve Sens'!T11*12%) -> 4400 | U11: ='IMS +ve Sens'!U11-('IMS +ve Sens'!U11*12%) -> 4400 | V11: ='IMS +ve Sens'!V11-('IMS +ve Sens'!V11*12%) -> 4400 | ... Z11: ='IMS +ve Sens'!Z11-('IMS +ve Sens'!Z11*12%) -> 3960 | AA11: =SUM(O11:Z11) -> 49280
A12: Al Fakher Two Apple Bahraini 250g | O12: ='IMS +ve Sens'!O12-('IMS +ve Sens'!O12*12%) -> 264 | P12: ='IMS +ve Sens'!P12-('IMS +ve Sens'!P12*12%) -> 264 | Q12: ='IMS +ve Sens'!Q12-('IMS +ve Sens'!Q12*12%) -> 220 | R12: ='IMS +ve Sens'!R12-('IMS +ve Sens'!R12*12%) -> 264 | S12: ='IMS +ve Sens'!S12-('IMS +ve Sens'!S12*12%) -> 264 | T12: ='IMS +ve Sens'!T12-('IMS +ve Sens'!T12*12%) -> 264 | U12: ='IMS +ve Sens'!U12-('IMS +ve Sens'!U12*12%) -> 264 | V12: ='IMS +ve Sens'!V12-('IMS +ve Sens'!V12*12%) -> 264 | ... Z12: ='IMS +ve Sens'!Z12-('IMS +ve Sens'!Z12*12%) -> 220 | AA12: =SUM(O12:Z12) -> 3036
A13: Al Fakher Blueberry Mint 50g | O13: ='IMS +ve Sens'!O13-('IMS +ve Sens'!O13*12%) -> 0 | P13: ='IMS +ve Sens'!P13-('IMS +ve Sens'!P13*12%) -> 0 | Q13: ='IMS +ve Sens'!Q13-('IMS +ve Sens'!Q13*12%) -> 0 | R13: ='IMS +ve Sens'!R13-('IMS +ve Sens'!R13*12%) -> 0 | S13: ='IMS +ve Sens'!S13-('IMS +ve Sens'!S13*12%) -> 0 | T13: ='IMS +ve Sens'!T13-('IMS +ve Sens'!T13*12%) -> 0 | U13: ='IMS +ve Sens'!U13-('IMS +ve Sens'!U13*12%) -> 0 | V13: ='IMS +ve Sens'!V13-('IMS +ve Sens'!V13*12%) -> 0 | ... Z13: ='IMS +ve Sens'!Z13-('IMS +ve Sens'!Z13*12%) -> 0 | AA13: =SUM(O13:Z13) -> 0
A14: Al Fakher Blueberry 50g | O14: ='IMS +ve Sens'!O14-('IMS +ve Sens'!O14*12%) -> 52.8 | P14: ='IMS +ve Sens'!P14-('IMS +ve Sens'!P14*12%) -> 52.8 | Q14: ='IMS +ve Sens'!Q14-('IMS +ve Sens'!Q14*12%) -> 52.8 | R14: ='IMS +ve Sens'!R14-('IMS +ve Sens'!R14*12%) -> 52.8 | S14: ='IMS +ve Sens'!S14-('IMS +ve Sens'!S14*12%) -> 52.8 | T14: ='IMS +ve Sens'!T14-('IMS +ve Sens'!T14*12%) -> 52.8 | U14: ='IMS +ve Sens'!U14-('IMS +ve Sens'!U14*12%) -> 52.8 | V14: ='IMS +ve Sens'!V14-('IMS +ve Sens'!V14*12%) -> 52.8 | ... Z14: ='IMS +ve Sens'!Z14-('IMS +ve Sens'!Z14*12%) -> 26.4 | AA14: =SUM(O14:Z14) -> 528
... A23: Al Fakher Two apple 50g | O23: ='IMS +ve Sens'!O23-('IMS +ve Sens'!O23*12%) -> 7040 | P23: ='IMS +ve Sens'!P23-('IMS +ve Sens'!P23*12%) -> 6160 | Q23: ='IMS +ve Sens'!Q23-('IMS +ve Sens'!Q23*12%) -> 5280 | R23: ='IMS +ve Sens'!R23-('IMS +ve Sens'!R23*12%) -> 6160 | S23: ='IMS +ve Sens'!S23-('IMS +ve Sens'!S23*12%) -> 6600 | T23: ='IMS +ve Sens'!T23-('IMS +ve Sens'!T23*12%) -> 6600 | U23: ='IMS +ve Sens'!U23-('IMS +ve Sens'!U23*12%) -> 6600 | V23: ='IMS +ve Sens'!V23-('IMS +ve Sens'!V23*12%) -> 6600 | ... Z23: ='IMS +ve Sens'!Z23-('IMS +ve Sens'!Z23*12%) -> 4400 | AA23: =SUM(O23:Z23) -> 70400
O24: ='IMS +ve Sens'!O32-('IMS +ve Sens'!O32*12%) -> 18532.8 | P24: ='IMS +ve Sens'!P32-('IMS +ve Sens'!P32*12%) -> 17102.8 | Q24: ='IMS +ve Sens'!Q32-('IMS +ve Sens'!Q32*12%) -> 16222.8 | R24: ='IMS +ve Sens'!R32-('IMS +ve Sens'!R32*12%) -> 18066.4 | S24: ='IMS +ve Sens'!S32-('IMS +ve Sens'!S32*12%) -> 19228 | T24: ='IMS +ve Sens'!T32-('IMS +ve Sens'!T32*12%) -> 19254.4 | U24: ='IMS +ve Sens'!U32-('IMS +ve Sens'!U32*12%) -> 19228 | V24: ='IMS +ve Sens'!V32-('IMS +ve Sens'!V32*12%) -> 19030 | ... Z24: ='IMS +ve Sens'!Z32-('IMS +ve Sens'!Z32*12%) -> 13512.4 | AA24: =SUM(O24:Z24) -> 205123.6

Sheet Shipment (Production)
B2: SKU Name | C2: 45658 | H2: 45689 | M2: 45717 | R2: 45748 | W2: 45778 | AB2: 45809 | AG2: 45839 | AL2: 45870 | AQ2: 45901 | AV2: 45931 | BA2: 45962 | BF2: 45992 | BK2: Total 2025 | BL2: 46023 | BQ2: 46054 | BV2: 46082 | CA2: 46113 | CF2: 46143 | CK2: 46174 | CP2: 46204 | CU2: 46235 | CZ2: 46266 | DE2: 46296 | DJ2: 46327 | DO2: 46357 | DT2: Total 2026 | DU2: 46388 | DZ2: 46419 | EE2: 46447 | EJ2: 46478 | EO2: 46508 | ET2: 46539 | EY2: 46569 | FD2: 46600 | FI2: 46631 | FN2: 46661 | FS2: 46692 | FX2: 46722 | GC2: Total 2026
C3: W1 | D3: W2 | E3: W3 | F3: W4 | G3: Total | H3: W1 | I3: W2 | J3: W3 | K3: W4 | L3: Total | M3: W1 | N3: W2 | O3: W3 | P3: W4 | Q3: Total | R3: W1 | S3: W2 | T3: W3 | U3: W4 | V3: Total | W3: W1 | X3: W2 | Y3: W3 | Z3: W4 | AA3: Total | AB3: W1 | AC3: W2 | AD3: W3 | AE3: W4 | AF3: Total | AG3: W1 | AH3: W2 | AI3: W3 | AJ3: W4 | AK3: Total | AL3: W1 | AM3: W2 | AN3: W3 | AO3: W4 | AP3: Total | AQ3: W1 | AR3: W2 | AS3: W3 | AT3: W4 | AU3: Total | AV3: W1 | AW3: W2 | AX3: W3 | AY3: W4 | AZ3: Total | BA3: W1 | BB3: W2 | BC3: W3 | BD3: W4 | BE3: Total | BF3: W1 | BG3: W2 | BH3: W3 | BI3: W4 | BJ3: Total | BL3: W1 | BM3: W2 | BN3: W3 | BO3: W4 | BP3: Total | BQ3: W1 | BR3: W2 | BS3: W3 | BT3: W4 | BU3: Total | BV3: W1 | BW3: W2 | BX3: W3 | BY3: W4 | BZ3: Total | CA3: W1 | CB3: W2 | CC3: W3 | CD3: W4 | CE3: Total | CF3: W1 | CG3: W2 | CH3: W3 | CI3: W4 | CJ3: Total | CK3: W1 | CL3: W2 | CM3: W3 | CN3: W4 | CO3: Total | CP3: W1 | CQ3: W2 | CR3: W3 | CS3: W4 | CT3: Total | CU3: W1 | CV3: W2 | CW3: W3 | CX3: W4 | CY3: Total | CZ3: W1 | DA3: W2 | DB3: W3 | DC3: W4 | DD3: Total | DE3: W1 | DF3: W2 | DG3: W3 | DH3: W4 | DI3: Total | DJ3: W1 | DK3: W2 | DL3: W3 | DM3: W4 | DN3: Total | DO3: W1 | DP3: W2 | DQ3: W3 | DR3: W4 | DS3: Total | DU3: W1 | DV3: W2 | DW3: W3 | DX3: W4 | DY3: Total | DZ3: W1 | EA3: W2 | EB3: W3 | EC3: W4 | ED3: Total | EE3: W1 | EF3: W2 | EG3: W3 | EH3: W4 | EI3: Total | EJ3: W1 | EK3: W2 | EL3: W3 | EM3: W4 | EN3: Total | EO3: W1 | EP3: W2 | EQ3: W3 | ER3: W4 | ES3: Total | ET3: W1 | EU3: W2 | EV3: W3 | EW3: W4 | EX3: Total | EY3: W1 | EZ3: W2 | FA3: W3 | FB3: W4 | FC3: Total | FD3: W1 | FE3: W2 | FF3: W3 | FG3: W4 | FH3: Total | FI3: W1 | FJ3: W2 | FK3: W3 | FL3: W4 | FM3: Total | FN3: W1 | FO3: W2 | FP3: W3 | FQ3: W4 | FR3: Total | FS3: W1 | FT3: W2 | FU3: W3 | FV3: W4 | FW3: Total | FX3: W1 | FY3: W2 | FZ3: W3 | GA3: W4 | GB3: Total
A4: 1kg | B4: Al Fakher Grapes & Mint 1kg | F4: 250 | G4: =SUM(C4:F4) -> 250 | L4: =SUM(H4:K4) -> 0 | P4: 770 | Q4: =SUM(M4:P4) -> 770 | V4: =SUM(R4:U4) -> 0 | AA4: =SUM(W4:Z4) -> 0 | AE4: 964 | AF4: =SUM(AB4:AE4) -> 964 | AK4: =SUM(AG4:AJ4) -> 0 | AO4: 261 | AP4: =SUM(AL4:AO4) -> 261 | AT4: 580 | AU4: =SUM(AQ4:AT4) -> 580 | AZ4: =SUM(AV4:AY4) -> 0 | BD4: 243 | BE4: =SUM(BA4:BD4) -> 243 | BI4: 497 | BJ4: =SUM(BF4:BI4) -> 497 | BK4: =G4+L4+Q4+V4+AA4+AF4+AK4+AP4+AU4+AZ4+BE4+BJ4 -> 3565 | BP4: =SUM(BL4:BO4) -> 0 | BT4: 200 | BU4: =SUM(BQ4:BT4) -> 200 | BY4: 380 | BZ4: =SUM(BV4:BY4) -> 380 | CE4: =SUM(CA4:CD4) -> 0 | CI4: 300 | CJ4: =SUM(CF4:CI4) -> 300 | CN4: 300 | CO4: =SUM(CK4:CN4) -> 300 | CS4: 200 | CT4: =SUM(CP4:CS4) -> 200 | CX4: 300 | CY4: =SUM(CU4:CX4) -> 300 | DC4: 300 | DD4: =SUM(CZ4:DC4) -> 300 | DH4: 250 | DI4: =SUM(DE4:DH4) -> 250 | DM4: 250 | DN4: =SUM(DJ4:DM4) -> 250 | DS4: =SUM(DO4:DR4) -> 0 | DT4: =BP4+BU4+BZ4+CE4+CJ4+CO4+CT4+CY4+DD4+DI4+DN4+DS4 -> 2480 | DU4: 250 | DY4: =SUM(DU4:DX4) -> 250 | DZ4: 230 | ED4: =SUM(DZ4:EC4) -> 230 | EE4: 244.8 | EI4: =SUM(EE4:EH4) -> 244.8 | EJ4: 285.6 | EN4: =SUM(EJ4:EM4) -> 285.6 | EO4: 306 | ES4: =SUM(EO4:ER4) -> 306 | ET4: 306 | EX4: =SUM(ET4:EW4) -> 306 | EY4: 306 | FC4: =SUM(EY4:FB4) -> 306 | FD4: 306 | FH4: =SUM(FD4:FG4) -> 306 | FI4: 255 | FM4: =SUM(FI4:FL4) -> 255 | FN4: 255 | FR4: =SUM(FN4:FQ4) -> 255 | FS4: 255 | FW4: =SUM(FS4:FV4) -> 255 | FX4: 255 | GB4: =SUM(FX4:GA4) -> 255 | GC4: =DU4+ED4+EI4+EN4+ES4+EX4+FC4+FH4+FM4+FR4+FW4+GB4 -> 3254.4
