Workbook

Sheet Regie Sales 2017
A1: Code | B1: Brand | C1: Name | D1: Qty | E1: 2017 Share %
A2: 5055 | B2: MOUASSAL 360 | C2: معسل 360 تفاحتين 50غ | D2: 3 | E2: =D2/$D$244 -> 1.0752573e-05
A3: 5287 | B3: LAYALINA | C3: غولدن ليالينا بلو هيفن 50غ | D3: 3 | E3: =D3/$D$244 -> 1.0752573e-05
A4: 5289 | B4: LAYALINA | C4: غولدن ليالينا كاليفورنيا دريم 50غ | D4: 3 | E4: =D4/$D$244 -> 1.0752573e-05
A5: 5291 | B5: LAYALINA | C5: غولدن ليالينا مانغو تانغو 50غ | D5: 3 | E5: =D5/$D$244 -> 1.0752573e-05
A6: 5295 | B6: LAYALINA | C6: غولدن ليالينا بلو هيفن 250غ | D6: 2 | E6: =D6/$D$244 -> 7.1683817e-06
A7: 5297 | B7: LAYALINA | C7: غولدن ليالينا مانغو تانغو 250غ | D7: 1 | E7: =D7/$D$244 -> 3.5841909e-06
A8: 5220 | B8: YA LAYL | C8: يا ليل بلوبيري 50غ | D8: 34 | E8: =D8/$D$244 -> 0.00012186249
A9: 5220 | B9: YA LAYL | C9: يا ليل بلوبيري 50غ | D9: 39 | E9: =D9/$D$244 -> 0.00013978344
A10: 5221 | B10: YA LAYL | C10: يا ليل تفاحتين 50غ | D10: 39 | E10: =D10/$D$244 -> 0.00013978344
A11: 5221 | B11: YA LAYL | C11: يا ليل تفاحتين 50غ | D11: 57 | E11: =D11/$D$244 -> 0.00020429888
A12: 5222 | B12: YA LAYL | C12: يا ليل عنب 50غ | D12: 5 | E12: =D12/$D$244 -> 1.7920954e-05
A13: 5222 | B13: YA LAYL | C13: يا ليل عنب 50غ | D13: 66 | E13: =D13/$D$244 -> 0.0002365566
... A243: 5137 | B243: NAKHLA | C243: نخلة حامض 250غ | D243: 138 | E243: =D243/$D$244 -> 0.00049461834
D244: 279003

Sheet Regie Sales 2018
A1: Code | B1: Brand | C1: Flavor | D1: Qty | E1: %
A2: 5287 | B2: LAYALINA | C2: غولدن ليالينا بلو هيفن 50غ | D2: 3 | E2: =D2/$D$169 -> 1.1309104e-05
A3: 5297 | B3: LAYALINA | C3: غولدن ليالينا مانغو تانغو 250غ | D3: 2 | E3: =D3/$D$169 -> 7.5394028e-06
A4: 5220 | B4: YA LAYL | C4: يا ليل بلوبيري 50غ | D4: 2 | E4: =D4/$D$169 -> 7.5394028e-06
A5: 5221 | B5: YA LAYL | C5: يا ليل تفاحتين 50غ | D5: 3 | E5: =D5/$D$169 -> 1.1309104e-05
A6: 5228 | B6: YA LAYL | C6: يا ليل ليمون 50غ | D6: 2 | E6: =D6/$D$169 -> 7.5394028e-06
A7: 5230 | B7: YA LAYL | C7: يا ليل تفاحتين 250غ | D7: 13 | E7: =D7/$D$169 -> 4.9006118e-05
A8: 5234 | B8: YA LAYL | C8: يا ليل حامض ونعنع 250غ | D8: 2 | E8: =D8/$D$169 -> 7.5394028e-06
A9: 5240 | B9: YA LAYL | C9: يا ليل حامض ونعنع 1 كلغ | D9: 4 | E9: =D9/$D$169 -> 1.5078806e-05
A10: 5242 | B10: YA LAYL | C10: يا ليل ليمون ونعنع 50غ | D10: 2 | E10: =D10/$D$169 -> 7.5394028e-06
A11: 5325 | B11: AL OSTOURA | C11: الأسطورة تفاحتين 50غ | D11: 50 | E11: =D11/$D$169 -> 0.00018848507
A12: 5326 | B12: AL OSTOURA | C12: الأسطورة حامض ونعنع 50غ | D12: 30 | E12: =D12/$D$169 -> 0.00011309104
A13: 5327 | B13: AL OSTOURA | C13: الأسطورة عنب ونعنع 50غ | D13: 3 | E13: =D13/$D$169 -> 1.1309104e-05
... A168: 5137 | B168: NAKHLA | C168: نخلة حامض 250غ | D168: 180 | E168: =D168/$D$169 -> 0.00067854625
D169: =SUM(D2:D168) -> 265273

Sheet Regie Sales 2019
A1: Codes | B1: Brand | C1: Flavors | D1: Brand Flavors | E1: Qty
A2: 5220 | B2: YA LAYL | D2: يا ليل بلوبيري 50غ | E2: 40 | F2: =E2/$E$221 -> 0.00015676315
A3: 5221 | B3: YA LAYL | D3: يا ليل تفاحتين 50غ | E3: 84 | F3: =E3/$E$221 -> 0.00032920262
A4: 5230 | B4: YA LAYL | D4: يا ليل تفاحتين 250غ | E4: 35 | F4: =E4/$E$221 -> 0.00013716776
A5: 5234 | B5: YA LAYL | D5: يا ليل حامض ونعنع 250غ | E5: 16 | F5: =E5/$E$221 -> 6.2705262e-05
A6: 5236 | B6: YA LAYL | D6: يا ليل تفاحتين 1 كلغ | E6: 23 | F6: =E6/$E$221 -> 9.0138814e-05
A7: 5240 | B7: YA LAYL | D7: يا ليل حامض ونعنع 1 كلغ | E7: 20 | F7: =E7/$E$221 -> 7.8381577e-05
A8: 5325 | B8: AL OSTOURA | C8: Two Apple | D8: الأسطورة تفاحتين 50غ | E8: 14 | F8: =E8/$E$221 -> 5.4867104e-05
A9: 5327 | B9: AL OSTOURA | C9: Grapes & Mint | D9: الأسطورة عنب ونعنع 50غ | E9: 7 | F9: =E9/$E$221 -> 2.7433552e-05
A10: 5328 | B10: AL OSTOURA | C10: Grapes | D10: الأسطورة عنب 50غ | E10: 7 | F10: =E10/$E$221 -> 2.7433552e-05
A11: 5329 | B11: AL OSTOURA | C11: Two Apple | D11: الأسطورة تفاحتين 250غ | E11: 16 | F11: =E11/$E$221 -> 6.2705262e-05
A12: 5330 | B12: AL OSTOURA | C12: Lemon & Mint | D12: الأسطورة حامض ونعنع 250غ | E12: 8 | F12: =E12/$E$221 -> 3.1352631e-05
A13: 5331 | B13: AL OSTOURA | C13: Grapes & Mint | D13: الأسطورة عنب ونعنع 250غ | E13: 2 | F13: =E13/$E$221 -> 7.8381577e-06
A14: 5332 | B14: AL OSTOURA | C14: Grapes | D14: الأسطورة عنب 250غ | E14: 2 | F14: =E14/$E$221 -> 7.8381577e-06
A15: 5317 | B15: AL TAMAYOZ | D15: معسل التميز عنب ونعناع 50غ | E15: 1 | F15: =E15/$E$221 -> 3.9190789e-06
A16: 5318 | B16: AL TAMAYOZ | D16: معسل التميز تفاحتين50غ | E16: 2 | F16: =E16/$E$221 -> 7.8381577e-06
A17: 5318 | B17: AL TAMAYOZ | D17: معسل التميز تفاحتين50غ | E17: 9 | F17: =E17/$E$221 -> 3.527171e-05
A18: 5319 | B18: AL TAMAYOZ | D18: معسل التميز ليمون ونعناع 50غ | E18: 1 | F18: =E18/$E$221 -> 3.9190789e-06
A19: 5319 | B19: AL TAMAYOZ | D19: معسل التميز ليمون ونعناع 50غ | E19: 7 | F19: =E19/$E$221 -> 2.7433552e-05
A20: 5320 | B20: AL TAMAYOZ | D20: التميز تفاحتين 250غ | E20: 3 | F20: =E20/$E$221 -> 1.1757237e-05
A21: 5321 | B21: AL TAMAYOZ | D21: التميز حامض ونعنع 250غ | E21: 1 | F21: =E21/$E$221 -> 3.9190789e-06
A22: 4738 | B22: AL FAKHER | C22: Two apple | D22: الفاخر تفاحتين بحريني 250غ | E22: 126 | F22: =E22/$E$221 -> 0.00049380394
A23: 4738 | B23: AL FAKHER | C23: Two apple | D23: الفاخر تفاحتين بحريني 250غ | E23: 168 | F23: =E23/$E$221 -> 0.00065840525
A24: 4738 | B24: AL FAKHER | C24: Two apple | D24: الفاخر تفاحتين بحريني 250غ | E24: 0 | F24: =E24/$E$221 -> 0
A25: 4770 | B25: AL FAKHER | C25: Lemon & Mint | D25: معسل الفاخر حامض ونعنع 50 غ | E25: 190 | F25: =E25/$E$221 -> 0.00074462498
A26: 4770 | B26: AL FAKHER | C26: Lemon & Mint | D26: معسل الفاخر حامض ونعنع 50 غ | E26: 400 | F26: =E26/$E$221 -> 0.0015676315
A27: 4770 | B27: AL FAKHER | C27: Lemon & Mint | D27: معسل الفاخر حامض ونعنع 50 غ | E27: 830 | F27: =E27/$E$221 -> 0.0032528355
A28: 4771 | B28: AL FAKHER | C28: Grapes & Mint | D28: معسل الفاخر عنب مع نعنع 50 غ | E28: 458 | F28: =E28/$E$221 -> 0.0017949381
A29: 4771 | B29: AL FAKHER | C29: Grapes & Mint | D29: معسل الفاخر عنب مع نعنع 50 غ | E29: 274 | F29: =E29/$E$221 -> 0.0010738276
A30: 4771 | B30: AL FAKHER | C30: Grapes & Mint | D30: معسل الفاخر عنب مع نعنع 50 غ | E30: 77 | F30: =E30/$E$221 -> 0.00030176907
A31: 4772 | B31: AL FAKHER | C31: Gum | D31: معسل الفاخر علكة 50 غ | E31: 5 | F31: =E31/$E$221 -> 1.9595394e-05
A32: 4772 | B32: AL FAKHER | C32: Gum | D32: معسل الفاخر علكة 50 غ | E32: 55 | F32: =E32/$E$221 -> 0.00021554934
A33: 4772 | B33: AL FAKHER | C33: Gum | D33: معسل الفاخر علكة 50 غ | E33: 70 | F33: =E33/$E$221 -> 0.00027433552
... A117: 5002 | B117: AL FAKHER | C117: Super Lemon Mint | D117: الفاخر سوبر ليمون ونعناع 1 كلغ | E117: 15 | F117: =E117/$E$221 -> 5.8786183e-05
A118: 5340 | B118: MALAKI | D118: ملكي حامض ونعنع 50غ | E118: 41 | F118: =E118/$E$221 -> 0.00016068223
A119: 5341 | B119: MALAKI | D119: ملكي حامض ونعنع 250غ | E119: 8 | F119: =E119/$E$221 -> 3.1352631e-05
A120: 5342 | B120: MALAKI | D120: ملكي تفاحتين 50غ | E120: 41 | F120: =E120/$E$221 -> 0.00016068223
A121: 5343 | B121: MALAKI | D121: ملكي تفاحتين 250غ | E121: 8 | F121: =E121/$E$221 -> 3.1352631e-05
A122: 5345 | B122: MALAKI | D122: ملكي عجمي وايلد 250غ | E122: 10 | F122: =E122/$E$221 -> 3.9190789e-05
A123: 5347 | B123: MALAKI | D123: ملكي عنب 250غ | E123: 8 | F123: =E123/$E$221 -> 3.1352631e-05
...

Sheet Regie Sales 2020
A1: Item | B1: Description | C1: Supplier | D1: Flavor | E1: Format | F1: SKU | G1: Weight/MasterCase | H1: Flavors Category | I1: Brand / Flavors Category | J1: Total MasterCase 2020 | K1: Total KG 2020 | L1: Total MasterCase 2022 | M1: Total KG 2022
A2: 4541 | B2: معسل أدخنة النخلة كرز 50 غ | C2: Nakhla | D2: Cherry | E2: 50g | F2: =C2&" "&D2&" "&E2 -> Nakhla Cherry 50g | G2: 12.5 | H2: Other Flavors | I2: =C2&" "&H2&"" -> Nakhla Other Flavors | J2: 396 | K2: =J2*G2 -> 4950 | L2: 208 | M2: =L2*G2 -> 2600
A3: 4545 | B3: معسل أدخنة النخلة تفاحتين 250غ معدن | C3: Nakhla | D3: Two Apple Tin | E3: 250g | F3: =C3&" "&D3&" "&E3 -> Nakhla Two Apple Tin 250g | G3: 10 | H3: Two Apple | I3: =C3&" "&H3&"" -> Nakhla Two Apple | J3: 2425 | K3: =J3*G3 -> 24250 | L3: 2772 | M3: =L3*G3 -> 27720
A4: 4546 | B4: معسل أدخنة النخلة نكهة الشمام 50غ | C4: Nakhla | D4: Melon | E4: 50g | F4: =C4&" "&D4&" "&E4 -> Nakhla Melon 50g | G4: 12.5 | H4: Other Flavors | I4: =C4&" "&H4&"" -> Nakhla Other Flavors | J4: 21 | K4: =J4*G4 -> 262.5 | L4: 108 | M4: =L4*G4 -> 1350
A5: 4549 | B5: معسل أدخنة النخلة تفاحتين بحريني 250 غ | C5: Nakhla | D5: Two Apple Bahraini | E5: 250g | F5: =C5&" "&D5&" "&E5 -> Nakhla Two Apple Bahraini 250g | G5: 10 | H5: Two Apple | I5: =C5&" "&H5&"" -> Nakhla Two Apple | J5: 60381 | K5: =J5*G5 -> 603810 | L5: 30641 | M5: =L5*G5 -> 306410
A6: 4551 | B6: معسل أدخنة النخلة زغلول 250غ | C6: Nakhla | D6: Zaghloul | E6: 250g | F6: =C6&" "&D6&" "&E6 -> Nakhla Zaghloul 250g | G6: 10 | H6: Other Flavors | I6: =C6&" "&H6&"" -> Nakhla Other Flavors | J6: 150 | K6: =J6*G6 -> 1500 | L6: 520 | M6: =L6*G6 -> 5200
A7: 4562 | B7: معسل أدخنة النخلة تفاحتين بحريني 50غ | C7: Nakhla | D7: Two Apple Bahraini | E7: 50g | F7: =C7&" "&D7&" "&E7 -> Nakhla Two Apple Bahraini 50g | G7: 10 | H7: Two Apple | I7: =C7&" "&H7&"" -> Nakhla Two Apple | J7: 85848 | K7: =J7*G7 -> 858480 | L7: 19575 | M7: =L7*G7 -> 195750
A8: 4563 | B8: معسل أدخنة النخلة زغلول 50 غ | C8: Nakhla | D8: Zaghloul | E8: 50g | F8: =C8&" "&D8&" "&E8 -> Nakhla Zaghloul 50g | G8: 12.5 | H8: Other Flavors | I8: =C8&" "&H8&"" -> Nakhla Other Flavors | J8: 123 | K8: =J8*G8 -> 1537.5 | L8: 584 | M8: =L8*G8 -> 7300
A9: 4738 | B9: الفاخر تفاحتين بحريني 250غ | C9: Al Fakher | D9: Two apple | E9: 250g | F9: =C9&" "&D9&" "&E9 -> Al Fakher Two apple 250g | G9: 6 | H9: Two Apple | I9: =C9&" "&H9&"" -> Al Fakher Two Apple | J9: 500 | K9: =J9*G9 -> 3000 | L9: 1358 | M9: =L9*G9 -> 8148
A10: 4770 | B10: معسل الفاخر حامض ونعنع 50 غ | C10: Al Fakher | D10: Lemon & Mint | E10: 50g | F10: =C10&" "&D10&" "&E10 -> Al Fakher Lemon & Mint 50g | G10: 6 | H10: lemon Mint | I10: =C10&" "&H10&"" -> Al Fakher lemon Mint | J10: 2207 | K10: =J10*G10 -> 13242 | L10: 2649 | M10: =L10*G10 -> 15894
A11: 4771 | B11: معسل الفاخر عنب مع نعنع 50 غ | C11: Al Fakher | D11: Grape Mint | E11: 50g | F11: =C11&" "&D11&" "&E11 -> Al Fakher Grape Mint 50g | G11: 6 | H11: Grape Mint | I11: =C11&" "&H11&"" -> Al Fakher Grape Mint | J11: 547 | K11: =J11*G11 -> 3282 | L11: 1825 | M11: =L11*G11 -> 10950
A12: 4772 | B12: معسل الفاخر علكه 50 غ | C12: Al Fakher | D12: Gum | E12: 50g | F12: =C12&" "&D12&" "&E12 -> Al Fakher Gum 50g | G12: 6 | H12: Gum | I12: =C12&" "&H12&"" -> Al Fakher Gum | J12: 114 | K12: =J12*G12 -> 684 | L12: 680 | M12: =L12*G12 -> 4080
A13: 4775 | B13: معسل الفاخر بطيخ 50 غ | C13: Al Fakher | D13: watermelon | E13: 50g | F13: =C13&" "&D13&" "&E13 -> Al Fakher watermelon 50g | G13: 6 | H13: Other Flavors | I13: =C13&" "&H13&"" -> Al Fakher Other Flavors | J13: 0 | K13: =J13*G13 -> 0 | L13: 150 | M13: =L13*G13 -> 900
... A59: 5002 | B59: الفاخر سوبر ليمون ونعناع 250غ | C59: Al Fakher | D59: Super Lemon Mint | E59: 250g | F59: =C59&" "&D59&" "&E59 -> Al Fakher Super Lemon Mint 250g | G59: 6 | H59: lemon Mint | I59: =C59&" "&H59&"" -> Al Fakher lemon Mint | J59: 6 | K59: =J59*G59 -> 36 | L59: 0 | M59: =L59*G59 -> 0
A60: 5012 | B60: شربتلي تفاحتين 250غ | C60: Sharbatli | D60: Two Apple | E60: 250g | F60: =C60&" "&D60&" "&E60 -> Sharbatli Two Apple 250g | G60: 6 | H60: Two Apple | I60: =C60&" "&H60&"" -> Sharbatli Two Apple | K60: =J60*G60 -> 0 | L60: 1 | M60: =L60*G60 -> 6
A61: 5013 | B61: شربتلي حامض ونعنع 50غ | C61: Sharbatli | D61: Lemon & Mint | E61: 50g | F61: =C61&" "&D61&" "&E61 -> Sharbatli Lemon & Mint 50g | G61: 6 | H61: lemon Mint | I61: =C61&" "&H61&"" -> Sharbatli lemon Mint | K61: =J61*G61 -> 0 | L61: 91 | M61: =L61*G61 -> 546
A62: 5014 | B62: شربتلي حامض ونعنع 250غ | C62: Sharbatli | D62: Lemon & Mint | E62: 250g | F62: =C62&" "&D62&" "&E62 -> Sharbatli Lemon & Mint 250g | G62: 6 | H62: lemon Mint | I62: =C62&" "&H62&"" -> Sharbatli lemon Mint | K62: =J62*G62 -> 0 | L62: 126 | M62: =L62*G62 -> 756
A63: 5019 | B63: شربتلي حامض ونعنع سوفت 50غ | C63: Sharbatli | D63: Lemon & Mint | E63: 50g | F63: =C63&" "&D63&" "&E63 -> Sharbatli Lemon & Mint 50g | G63: 6 | H63: lemon Mint | I63: =C63&" "&H63&"" -> Sharbatli lemon Mint | K63: =J63*G63 -> 0 | L63: 25 | M63: =L63*G63 -> 150
A64: 5021 | B64: شربتلي كوفي كريم 50غ | C64: Sharbatli | D64: Coffee Cream | E64: 50g | F64: =C64&" "&D64&" "&E64 -> Sharbatli Coffee Cream 50g | G64: 6 | H64: Other Flavors | I64: =C64&" "&H64&"" -> Sharbatli Other Flavors | K64: =J64*G64 -> 0 | L64: 30 | M64: =L64*G64 -> 180
A65: 5120 | B65: الهنا تفاحتين 50غ | C65: Al Hana | D65: Two Apple | E65: 50g | F65: =C65&" "&D65&" "&E65 -> Al Hana Two Apple 50g | G65: 6 | H65: Two Apple | I65: =C65&" "&H65&"" -> Al Hana Two Apple | J65: 0 | K65: =J65*G65 -> 0 | L65: 498 | M65: =L65*G65 -> 2988
A66: 5121 | B66: الهنا تفاحتين 250غ | C66: Al Hana | D66: Two Apple | E66: 250g | F66: =C66&" "&D66&" "&E66 -> Al Hana Two Apple 250g | G66: 6 | H66: Two Apple | I66: =C66&" "&H66&"" -> Al Hana Two Apple | J66: 0 | K66: =J66*G66 -> 0 | L66: 311 | M66: =L66*G66 -> 1866
A67: 5122 | B67: الهنا حامض ونعنع 50غ | C67: Al Hana | D67: Lemon & Mint | E67: 50g | F67: =C67&" "&D67&" "&E67 -> Al Hana Lemon & Mint 50g | G67: 6 | H67: lemon Mint | I67: =C67&" "&H67&"" -> Al Hana lemon Mint | J67: 0 | K67: =J67*G67 -> 0 | L67: 686 | M67: =L67*G67 -> 4116
A68: 5123 | B68: الهنا حامض ونعنع 250غ | C68: Al Hana | D68: Lemon & Mint | E68: 250g | F68: =C68&" "&D68&" "&E68 -> Al Hana Lemon & Mint 250g | G68: 6 | H68: lemon Mint | I68: =C68&" "&H68&"" -> Al Hana lemon Mint | J68: 0 | K68: =J68*G68 -> 0 | L68: 301 | M68: =L68*G68 -> 1806
A69: 5124 | B69: الهنا علكه و نعنع 50غ | C69: Al Hana | D69: Gum & mint | E69: 50g | F69: =C69&" "&D69&" "&E69 -> Al Hana Gum & mint 50g | G69: 6 | H69: Gum | I69: =C69&" "&H69&"" -> Al Hana Gum | J69: 0 | K69: =J69*G69 -> 0 | L69: 77 | M69: =L69*G69 -> 462
A70: 5125 | B70: الهنا علكه و نعنع 250 غ | C70: Al Hana | D70: Gum & mint | E70: 250g | F70: =C70&" "&D70&" "&E70 -> Al Hana Gum & mint 250g | G70: 6 | H70: Gum | I70: =C70&" "&H70&"" -> Al Hana Gum | J70: 0 | K70: =J70*G70 -> 0 | L70: 25 | M70: =L70*G70 -> 150
A71: 5126 | B71: الهنا عنب و نعنع 50غ | C71: Al Hana | D71: Grape Mint | E71: 50g | F71: =C71&" "&D71&" "&E71 -> Al Hana Grape Mint 50g | G71: 6 | H71: Grape Mint | I71: =C71&" "&H71&"" -> Al Hana Grape Mint | J71: 0 | K71: =J71*G71 -> 0 | L71: 187 | M71: =L71*G71 -> 1122
A72: 5127 | B72: الهنا عنب و نعنع 250غ | C72: Al Hana | D72: Grape Mint | E72: 250g | F72: =C72&" "&D72&" "&E72 -> Al Hana Grape Mint 250g | G72: 6 | H72: Grape Mint | I72: =C72&" "&H72&"" -> Al Hana Grape Mint | J72: 0 | K72: =J72*G72 -> 0 | L72: 0 | M72: =L72*G72 -> 0
A73: 5128 | B73: الهنا سامر فايب 50غ | C73: Al Hana | D73: Summer Vape | E73: 50g | F73: =C73&" "&D73&" "&E73 -> Al Hana Summer Vape 50g | G73: 6 | H73: Other Flavors | I73: =C73&" "&H73&"" -> Al Hana Other Flavors | J73: 0 | K73: =J73*G73 -> 0 | L73: 85 | M73: =L73*G73 -> 510
A74: 5129 | B74: الهنا سامر فايب 250 غ | C74: Al Hana | D74: Summer Vape | E74: 250g | F74: =C74&" "&D74&" "&E74 -> Al Hana Summer Vape 250g | G74: 6 | H74: Other Flavors | I74: =C74&" "&H74&"" -> Al Hana Other Flavors | J74: 0 | K74: =J74*G74 -> 0 | L74: 0 | M74: =L74*G74 -> 0
A75: 5131 | B75: نخلة نعنع 50غ | C75: Nakhla | D75: Peach | E75: 50g | F75: =C75&" "&D75&" "&E75 -> Nakhla Peach 50g | G75: 12.5 | H75: Other Flavors | I75: =C75&" "&H75&"" -> Nakhla Other Flavors | J75: 0 | K75: =J75*G75 -> 0 | L75: 0 | M75: =L75*G75 -> 0
A76: 5132 | B76: نخلة حامض 50غ | C76: Nakhla | D76: Lemon | E76: 50g | F76: =C76&" "&D76&" "&E76 -> Nakhla Lemon 50g | G76: 12.5 | H76: Other Flavors | I76: =C76&" "&H76&"" -> Nakhla Other Flavors | J76: 89 | K76: =J76*G76 -> 1112.5 | L76: 84 | M76: =L76*G76 -> 1050
... A82: 5139 | B82: نخلة عنب 50غ | C82: Nakhla | D82: Grapes | E82: 50g | F82: =C82&" "&D82&" "&E82 -> Nakhla Grapes 50g | G82: 12.5 | H82: Grapes | I82: =C82&" "&H82&"" -> Nakhla Grapes | J82: 70 | K82: =J82*G82 -> 875 | L82: 209 | M82: =L82*G82 -> 2612.5
A83: 5140 | B83: نخله عنب 250غ | C83: Nakhla | D83: Grapes | E83: 250 | F83: =C83&" "&D83&" "&E83 -> Nakhla Grapes 250 | G83: 12.5 | H83: Grapes | I83: =C83&" "&H83&"" -> Nakhla Grapes | K83: =J83*G83 -> 0 | L83: 157 | M83: =L83*G83 -> 1962.5
A84: 5145 | B84: نخله تفاحتين 50غ | C84: Nakhla | D84: Two Apple | E84: 50g | F84: =C84&" "&D84&" "&E84 -> Nakhla Two Apple 50g | G84: 12.5 | H84: Two Apple | I84: =C84&" "&H84&"" -> Nakhla Two Apple | K84: =J84*G84 -> 0 | L84: 33372 | M84: =L84*G84 -> 417150
A85: 5146 | B85: نخله تفاحتين 250غ | C85: Nakhla | D85: Two Apple | E85: 250g | F85: =C85&" "&D85&" "&E85 -> Nakhla Two Apple 250g | G85: 10 | H85: Two Apple | I85: =C85&" "&H85&"" -> Nakhla Two Apple | K85: =J85*G85 -> 0 | L85: 53929 | M85: =L85*G85 -> 539290
A86: 5162 | B86: الهنا لوف 50 غ | C86: Al Hana | D86: Love | E86: 50g | F86: =C86&" "&D86&" "&E86 -> Al Hana Love 50g | G86: 6 | H86: Other Flavors | I86: =C86&" "&H86&"" -> Al Hana Other Flavors | J86: 0 | K86: =J86*G86 -> 0 | L86: 0 | M86: =L86*G86 -> 0
A87: 5163 | B87: الهنا بلوبيري 50 غ | C87: Al Hana | D87: Blueberry | E87: 50g | F87: =C87&" "&D87&" "&E87 -> Al Hana Blueberry 50g | G87: 6 | H87: Other Flavors | I87: =C87&" "&H87&"" -> Al Hana Other Flavors | J87: 0 | K87: =J87*G87 -> 0 | L87: 54 | M87: =L87*G87 -> 324
A88: 5304 | B88: الأسطورة تفاحتين بحريني 1 كلغ | C88: Al Ostoura | D88: Two Apple Bahraini | E88: 1Kg | F88: =C88&" "&D88&" "&E88 -> Al Ostoura Two Apple Bahraini 1Kg | G88: 6 | H88: Two Apple | I88: =C88&" "&H88&"" -> Al Ostoura Two Apple | K88: =J88*G88 -> 0 | L88: 31 | M88: =L88*G88 -> 186
A89: 5305 | B89: الأسطورة برتقال 50غ | C89: Al Ostoura | D89: Orange | E89: 50g | F89: =C89&" "&D89&" "&E89 -> Al Ostoura Orange 50g | G89: 6 | H89: Other Flavors | I89: =C89&" "&H89&"" -> Al Ostoura Other Flavors | J89: 0 | K89: =J89*G89 -> 0 | L89: 0 | M89: =L89*G89 -> 0
A90: 5306 | B90: الأسطورة برتقال ونعنع 50غ | C90: Al Ostoura | D90: Orange & Mint | E90: 50g | F90: =C90&" "&D90&" "&E90 -> Al Ostoura Orange & Mint 50g | G90: 6 | H90: Other Flavors | I90: =C90&" "&H90&"" -> Al Ostoura Other Flavors | J90: 0 | K90: =J90*G90 -> 0 | L90: 0 | M90: =L90*G90 -> 0
...

Sheet Regie Sales 2021
A1: Item | B1: Description | C1: Supplier | D1: Flavor | E1: Format | F1: SKU | G1: Weight/MasterCase | H1: Flavors Category | I1: Brand / Flavors Category | J1: Total MasterCase 2021 | K1: Total KG 2021
A2: 4541 | B2: معسل أدخنة النخلة كرز 50 غ | C2: Nakhla | D2: Cherry | E2: 50g | F2: =C2&" "&D2&" "&E2 -> Nakhla Cherry 50g | G2: 12.5 | H2: Other Flavors | I2: =F2 -> Nakhla Cherry 50g | J2: 42 | K2: =J2*'Regie Sales 2020'!G2 -> 525
A3: 4545 | B3: معسل أدخنة النخلة تفاحتين 250غ معدن | C3: Nakhla | D3: Two Apple Tin | E3: 250g | F3: =C3&" "&D3&" "&E3 -> Nakhla Two Apple Tin 250g | G3: 10 | H3: Two Apple | I3: =F3 -> Nakhla Two Apple Tin 250g | J3: 3461 | K3: =J3*'Regie Sales 2020'!G3 -> 34610
A4: 4546 | B4: معسل أدخنة النخلة نكهة الشمام 50غ | C4: Nakhla | D4: Melon | E4: 50g | F4: =C4&" "&D4&" "&E4 -> Nakhla Melon 50g | G4: 12.5 | H4: Other Flavors | I4: =F4 -> Nakhla Melon 50g | J4: 31 | K4: =J4*'Regie Sales 2020'!G4 -> 387.5
A5: 4549 | B5: معسل أدخنة النخلة تفاحتين بحريني 250 غ | C5: Nakhla | D5: Two Apple Bahraini | E5: 250g | F5: =C5&" "&D5&" "&E5 -> Nakhla Two Apple Bahraini 250g | G5: 10 | H5: Two Apple | I5: =F5 -> Nakhla Two Apple Bahraini 250g | J5: 78993 | K5: =J5*'Regie Sales 2020'!G5 -> 789930
A6: 4551 | B6: معسل أدخنة النخلة زغلول 250غ | C6: Nakhla | D6: Zaghloul | E6: 250g | F6: =C6&" "&D6&" "&E6 -> Nakhla Zaghloul 250g | G6: 10 | H6: Other Flavors | I6: =F6 -> Nakhla Zaghloul 250g | J6: 450 | K6: =J6*'Regie Sales 2020'!G6 -> 4500
A7: 4562 | B7: معسل أدخنة النخلة تفاحتين بحريني 50غ | C7: Nakhla | D7: Two Apple Bahraini | E7: 50g | F7: =C7&" "&D7&" "&E7 -> Nakhla Two Apple Bahraini 50g | G7: 10 | H7: Two Apple | I7: =F7 -> Nakhla Two Apple Bahraini 50g | J7: 69546 | K7: =J7*'Regie Sales 2020'!G7 -> 695460
A8: 4563 | B8: معسل أدخنة النخلة زغلول 50 غ | C8: Nakhla | D8: Zaghloul | E8: 50g | F8: =C8&" "&D8&" "&E8 -> Nakhla Zaghloul 50g | G8: 12.5 | H8: Other Flavors | I8: =F8 -> Nakhla Zaghloul 50g | J8: 450 | K8: =J8*'Regie Sales 2020'!G8 -> 5625
A9: 4738 | B9: الفاخر تفاحتين بحريني 250غ | C9: Al Fakher | D9: Two apple | E9: 250g | F9: =C9&" "&D9&" "&E9 -> Al Fakher Two apple 250g | G9: 6 | H9: Two Apple | I9: =F9 -> Al Fakher Two apple 250g | J9: 1950 | K9: =J9*'Regie Sales 2020'!G9 -> 11700
A10: 4770 | B10: معسل الفاخر حامض ونعنع 50 غ | C10: Al Fakher | D10: Lemon Mint | E10: 50g | F10: =C10&" "&D10&" "&E10 -> Al Fakher Lemon Mint 50g | G10: 6 | H10: lemon Mint | I10: =F10 -> Al Fakher Lemon Mint 50g | J10: 2208 | K10: =J10*'Regie Sales 2020'!G10 -> 13248
A11: 4771 | B11: معسل الفاخر عنب مع نعنع 50 غ | C11: Al Fakher | D11: Grape Mint | E11: 50g | F11: =C11&" "&D11&" "&E11 -> Al Fakher Grape Mint 50g | G11: 6 | H11: Grapes Mint | I11: =F11 -> Al Fakher Grape Mint 50g | J11: 2620 | K11: =J11*'Regie Sales 2020'!G11 -> 15720
A12: 4772 | B12: معسل الفاخر علكه 50 غ | C12: Al Fakher | D12: Gum | E12: 50g | F12: =C12&" "&D12&" "&E12 -> Al Fakher Gum 50g | G12: 6 | H12: Gum | I12: =F12 -> Al Fakher Gum 50g | J12: 370 | K12: =J12*'Regie Sales 2020'!G12 -> 2220
A13: 4775 | B13: معسل الفاخر بطيخ 50 غ | C13: Al Fakher | D13: watermelon | E13: 50g | F13: =C13&" "&D13&" "&E13 -> Al Fakher watermelon 50g | G13: 6 | H13: Other Flavors | I13: =F13 -> Al Fakher watermelon 50g | J13: 170 | K13: =J13*'Regie Sales 2020'!G13 -> 1020
... A59: 5002 | B59: الفاخر سوبر ليمون ونعناع 250غ | C59: Al Fakher | D59: Super Lemon Mint | E59: 250g | F59: =C59&" "&D59&" "&E59 -> Al Fakher Super Lemon Mint 250g | G59: 6 | H59: lemon Mint | I59: =F59 -> Al Fakher Super Lemon Mint 250g | J59: 0 | K59: =J59*'Regie Sales 2020'!G59 -> 0
A60: 5012 | B60: شربتلي تفاحتين 250غ | C60: Sharbatli | D60: Two Apple | E60: 250g | F60: =C60&" "&D60&" "&E60 -> Sharbatli Two Apple 250g | G60: 6 | H60: Two Apple | I60: =F60 -> Sharbatli Two Apple 250g | K60: =J60*'Regie Sales 2020'!G60 -> 0
A61: 5013 | B61: شربتلي حامض ونعنع 50غ | C61: Sharbatli | D61: Lemon Mint | E61: 50g | F61: =C61&" "&D61&" "&E61 -> Sharbatli Lemon Mint 50g | G61: 6 | H61: lemon Mint | I61: =F61 -> Sharbatli Lemon Mint 50g | K61: =J61*'Regie Sales 2020'!G61 -> 0
A62: 5014 | B62: شربتلي حامض ونعنع 250غ | C62: Sharbatli | D62: Lemon Mint | E62: 250g | F62: =C62&" "&D62&" "&E62 -> Sharbatli Lemon Mint 250g | G62: 6 | H62: lemon Mint | I62: =F62 -> Sharbatli Lemon Mint 250g | K62: =J62*'Regie Sales 2020'!G62 -> 0
A63: 5019 | B63: شربتلي حامض ونعنع سوفت 50غ | C63: Sharbatli | D63: Lemon Mint | E63: 50g | F63: =C63&" "&D63&" "&E63 -> Sharbatli Lemon Mint 50g | G63: 6 | H63: lemon Mint | I63: =F63 -> Sharbatli Lemon Mint 50g | K63: =J63*'Regie Sales 2020'!G63 -> 0
A64: 5021 | B64: شربتلي كوفي كريم 50غ | C64: Sharbatli | D64: Coffee Cream | E64: 50g | F64: =C64&" "&D64&" "&E64 -> Sharbatli Coffee Cream 50g | G64: 6 | H64: Other Flavors | I64: =F64 -> Sharbatli Coffee Cream 50g | K64: =J64*'Regie Sales 2020'!G64 -> 0
A65: 5120 | B65: الهنا تفاحتين 50غ | C65: Al Hana | D65: Two Apple | E65: 50g | F65: =C65&" "&D65&" "&E65 -> Al Hana Two Apple 50g | G65: 6 | H65: Two Apple | I65: =F65 -> Al Hana Two Apple 50g | J65: 1391 | K65: =J65*'Regie Sales 2020'!G65 -> 8346
A66: 5121 | B66: الهنا تفاحتين 250غ | C66: Al Hana | D66: Two Apple | E66: 250g | F66: =C66&" "&D66&" "&E66 -> Al Hana Two Apple 250g | G66: 6 | H66: Two Apple | I66: =F66 -> Al Hana Two Apple 250g | J66: 524 | K66: =J66*'Regie Sales 2020'!G66 -> 3144
A67: 5122 | B67: الهنا حامض ونعنع 50غ | C67: Al Hana | D67: Lemon Mint | E67: 50g | F67: =C67&" "&D67&" "&E67 -> Al Hana Lemon Mint 50g | G67: 6 | H67: lemon Mint | I67: =F67 -> Al Hana Lemon Mint 50g | J67: 720 | K67: =J67*'Regie Sales 2020'!G67 -> 4320
A68: 5123 | B68: الهنا حامض ونعنع 250غ | C68: Al Hana | D68: Lemon Mint | E68: 250g | F68: =C68&" "&D68&" "&E68 -> Al Hana Lemon Mint 250g | G68: 6 | H68: lemon Mint | I68: =F68 -> Al Hana Lemon Mint 250g | J68: 244 | K68: =J68*'Regie Sales 2020'!G68 -> 1464
A69: 5124 | B69: الهنا علكه و نعنع 50غ | C69: Al Hana | D69: Gum & mint | E69: 50g | F69: =C69&" "&D69&" "&E69 -> Al Hana Gum & mint 50g | G69: 6 | H69: Gum | I69: =F69 -> Al Hana Gum & mint 50g | J69: 174 | K69: =J69*'Regie Sales 2020'!G69 -> 1044
A70: 5125 | B70: الهنا علكه و نعنع 250 غ | C70: Al Hana | D70: Gum & mint | E70: 250g | F70: =C70&" "&D70&" "&E70 -> Al Hana Gum & mint 250g | G70: 6 | H70: Gum | I70: =F70 -> Al Hana Gum & mint 250g | J70: 96 | K70: =J70*'Regie Sales 2020'!G70 -> 576
A71: 5126 | B71: الهنا عنب و نعنع 50غ | C71: Al Hana | D71: Grape Mint | E71: 50g | F71: =C71&" "&D71&" "&E71 -> Al Hana Grape Mint 50g | G71: 6 | H71: Grapes Mint | I71: =F71 -> Al Hana Grape Mint 50g | J71: 303 | K71: =J71*'Regie Sales 2020'!G71 -> 1818
A72: 5127 | B72: الهنا عنب و نعنع 250غ | C72: Al Hana | D72: Grape Mint | E72: 250g | F72: =C72&" "&D72&" "&E72 -> Al Hana Grape Mint 250g | G72: 6 | H72: Grapes Mint | I72: =F72 -> Al Hana Grape Mint 250g | J72: 156 | K72: =J72*'Regie Sales 2020'!G72 -> 936
A73: 5128 | B73: الهنا سامر فايب 50غ | C73: Al Hana | D73: Summer Vape | E73: 50g | F73: =C73&" "&D73&" "&E73 -> Al Hana Summer Vape 50g | G73: 6 | H73: Other Flavors | I73: =F73 -> Al Hana Summer Vape 50g | J73: 240 | K73: =J73*'Regie Sales 2020'!G73 -> 1440
A74: 5129 | B74: الهنا سامر فايب 250 غ | C74: Al Hana | D74: Summer Vape | E74: 250g | F74: =C74&" "&D74&" "&E74 -> Al Hana Summer Vape 250g | G74: 6 | H74: Other Flavors | I74: =F74 -> Al Hana Summer Vape 250g | J74: 88 | K74: =J74*'Regie Sales 2020'!G74 -> 528
A75: 5131 | B75: نخلة نعنع 50غ | C75: Nakhla | D75: Peach | E75: 50g | F75: =C75&" "&D75&" "&E75 -> Nakhla Peach 50g | G75: 12.5 | H75: Other Flavors | I75: =F75 -> Nakhla Peach 50g | J75: 0 | K75: =J75*'Regie Sales 2020'!G75 -> 0
A76: 5132 | B76: نخلة حامض 50غ | C76: Nakhla | D76: Lemon | E76: 50g | F76: =C76&" "&D76&" "&E76 -> Nakhla Lemon 50g | G76: 12.5 | H76: Other Flavors | I76: =F76 -> Nakhla Lemon 50g | J76: 84 | K76: =J76*'Regie Sales 2020'!G76 -> 1050
... A82: 5139 | B82: نخلة عنب 50غ | C82: Nakhla | D82: Grapes | E82: 50g | F82: =C82&" "&D82&" "&E82 -> Nakhla Grapes 50g | G82: 12.5 | H82: Grapes | I82: =F82 -> Nakhla Grapes 50g | J82: 39 | K82: =J82*'Regie Sales 2020'!G82 -> 487.5
A83: 5140 | B83: نخله عنب 250غ | C83: Nakhla | D83: Grapes | E83: 250 | F83: =C83&" "&D83&" "&E83 -> Nakhla Grapes 250 | G83: 12.5 | H83: Grapes | I83: =F83 -> Nakhla Grapes 250 | K83: =J83*'Regie Sales 2020'!G83 -> 0
A84: 5145 | B84: نخله تفاحتين 50غ | C84: Nakhla | D84: Two Apple | E84: 50g | F84: =C84&" "&D84&" "&E84 -> Nakhla Two Apple 50g | G84: 12.5 | H84: Two Apple | I84: =F84 -> Nakhla Two Apple 50g | K84: =J84*'Regie Sales 2020'!G84 -> 0
A85: 5146 | B85: نخله تفاحتين 250غ | C85: Nakhla | D85: Two Apple | E85: 250g | F85: =C85&" "&D85&" "&E85 -> Nakhla Two Apple 250g | G85: 10 | H85: Two Apple | I85: =F85 -> Nakhla Two Apple 250g | K85: =J85*'Regie Sales 2020'!G85 -> 0
A86: 5162 | B86: الهنا لوف 50 غ | C86: Al Hana | D86: Love | E86: 50g | F86: =C86&" "&D86&" "&E86 -> Al Hana Love 50g | G86: 6 | H86: Other Flavors | I86: =F86 -> Al Hana Love 50g | J86: 7 | K86: =J86*'Regie Sales 2020'!G86 -> 42
A87: 5163 | B87: الهنا بلوبيري 50 غ | C87: Al Hana | D87: Blueberry | E87: 50g | F87: =C87&" "&D87&" "&E87 -> Al Hana Blueberry 50g | G87: 6 | H87: Other Flavors | I87: =F87 -> Al Hana Blueberry 50g | J87: 8 | K87: =J87*'Regie Sales 2020'!G87 -> 48
A88: 5304 | B88: الأسطورة تفاحتين بحريني 1 كلغ | C88: Al Ostoura | D88: Two Apple Bahraini | E88: 1Kg | F88: =C88&" "&D88&" "&E88 -> Al Ostoura Two Apple Bahraini 1Kg | G88: 6 | H88: Two Apple | I88: =F88 -> Al Ostoura Two Apple Bahraini 1Kg | K88: =J88*'Regie Sales 2020'!G88 -> 0
A89: 5305 | B89: الأسطورة برتقال 50غ | C89: Al Ostoura | D89: Orange | E89: 50g | F89: =C89&" "&D89&" "&E89 -> Al Ostoura Orange 50g | G89: 6 | H89: Other Flavors | I89: =F89 -> Al Ostoura Orange 50g | J89: 25 | K89: =J89*'Regie Sales 2020'!G89 -> 150
A90: 5306 | B90: الأسطورة برتقال ونعنع 50غ | C90: Al Ostoura | D90: Orange & Mint | E90: 50g | F90: =C90&" "&D90&" "&E90 -> Al Ostoura Orange & Mint 50g | G90: 6 | H90: Other Flavors | I90: =F90 -> Al Ostoura Orange & Mint 50g | J90: 25 | K90: =J90*'Regie Sales 2020'!G90 -> 150
...

Sheet Regie Sales 2022
A1: Item | B1: Description | C1: Supplier | D1: Flavor | E1: Format | F1: SKU | G1: Jan | H1: Feb | I1: March | J1: Apr | K1: May | L1: June | M1: July | N1: Aug | O1: Sep | P1: Oct | Q1: Nov | R1: Dec | S1: Total | T1: SKU | U1: Weight/MasterCase | V1: Jan | W1: Feb | X1: March | Y1: Apr | Z1: May | AA1: June | AB1: July | AC1: Aug | AD1: Sep | AE1: Oct | AF1: Nov | AG1: Dec | AH1: Total | AI1: Flavors | AJ1: Brand/Flavors | AK1: MasterCase | AL1: KG | AM1: 2022 Share %
A2: 4541 | B2: معسل أدخنة النخلة كرز 50 غ | C2: Nakhla | D2: Cherry | E2: 50g | F2: =C2&" "&D2&" "&E2 -> Nakhla Cherry 50g | G2: 3 | H2: 75 | I2: 75 | N2: 55 | S2: =SUM(G2:R2) -> 208 | T2: =F2 -> Nakhla Cherry 50g | U2: 12.5 | V2: =G2*$U2 -> 37.5 | W2: =H2*$U2 -> 937.5 | X2: =I2*$U2 -> 937.5 | Y2: =J2*$U2 -> 0 | Z2: =K2*$U2 -> 0 | AA2: =L2*$U2 -> 0 | AB2: =M2*$U2 -> 0 | AC2: =N2*$U2 -> 687.5 | ... AG2: =R2*$U2 -> 0 | AH2: =SUM(V2:AG2) -> 2600 | AI2: Other Flavors | AJ2: =C2&" "&AI2&"" -> Nakhla Other Flavors | AK2: =S2 -> 208 | AL2: =AH2 -> 2600 | AM2: =AL2/$AL$185 -> 0.00061805682
A3: 4545 | B3: معسل أدخنة النخلة تفاحتين 250غ معدن | C3: Nakhla | D3: Two Apple Tin | E3: 250g | F3: =C3&" "&D3&" "&E3 -> Nakhla Two Apple Tin 250g | G3: 15 | H3: 738 | I3: 1835 | J3: 184 | S3: =SUM(G3:R3) -> 2772 | T3: =F3 -> Nakhla Two Apple Tin 250g | U3: 10 | V3: =G3*$U3 -> 150 | W3: =H3*$U3 -> 7380 | X3: =I3*$U3 -> 18350 | Y3: =J3*$U3 -> 1840 | Z3: =K3*$U3 -> 0 | AA3: =L3*$U3 -> 0 | AB3: =M3*$U3 -> 0 | AC3: =N3*$U3 -> 0 | ... AG3: =R3*$U3 -> 0 | AH3: =SUM(V3:AG3) -> 27720 | AI3: Two Apple | AJ3: =C3&" "&AI3&"" -> Nakhla Two Apple | AK3: =S3 -> 2772 | AL3: =AH3 -> 27720 | AM3: =AL3/$AL$185 -> 0.0065894365
A4: 4546 | B4: معسل أدخنة النخلة نكهة الشمام 50غ | C4: Nakhla | D4: Melon | E4: 50g | F4: =C4&" "&D4&" "&E4 -> Nakhla Melon 50g | H4: 83 | I4: 17 | L4: 3 | N4: 5 | S4: =SUM(G4:R4) -> 108 | T4: =F4 -> Nakhla Melon 50g | U4: 12.5 | V4: =G4*$U4 -> 0 | W4: =H4*$U4 -> 1037.5 | X4: =I4*$U4 -> 212.5 | Y4: =J4*$U4 -> 0 | Z4: =K4*$U4 -> 0 | AA4: =L4*$U4 -> 37.5 | AB4: =M4*$U4 -> 0 | AC4: =N4*$U4 -> 62.5 | ... AG4: =R4*$U4 -> 0 | AH4: =SUM(V4:AG4) -> 1350 | AI4: Other Flavors | AJ4: =C4&" "&AI4&"" -> Nakhla Other Flavors | AK4: =S4 -> 108 | AL4: =AH4 -> 1350 | AM4: =AL4/$AL$185 -> 0.00032091412
A5: 4549 | B5: معسل أدخنة النخلة تفاحتين بحريني 250 غ | C5: Nakhla | D5: Two Apple Bahraini | E5: 250g | F5: =C5&" "&D5&" "&E5 -> Nakhla Two Apple Bahraini 250g | G5: 2224 | H5: 6616 | I5: 12452 | J5: 5864 | L5: 3468 | M5: 17 | S5: =SUM(G5:R5) -> 30641 | T5: =F5 -> Nakhla Two Apple Bahraini 250g | U5: 10 | V5: =G5*$U5 -> 22240 | W5: =H5*$U5 -> 66160 | X5: =I5*$U5 -> 124520 | Y5: =J5*$U5 -> 58640 | Z5: =K5*$U5 -> 0 | AA5: =L5*$U5 -> 34680 | AB5: =M5*$U5 -> 170 | AC5: =N5*$U5 -> 0 | ... AG5: =R5*$U5 -> 0 | AH5: =SUM(V5:AG5) -> 306410 | AI5: Two Apple | AJ5: =C5&" "&AI5&"" -> Nakhla Two Apple | AK5: =S5 -> 30641 | AL5: =AH5 -> 306410 | AM5: =AL5/$AL$185 -> 0.072837996
A6: 4551 | B6: معسل أدخنة النخلة زغلول 250غ | C6: Nakhla | D6: Zaghloul | E6: 250g | F6: =C6&" "&D6&" "&E6 -> Nakhla Zaghloul 250g | H6: 78 | I6: 37 | J6: 79 | L6: 65 | O6: 5 | Q6: 116 | R6: 140 | S6: =SUM(G6:R6) -> 520 | T6: =F6 -> Nakhla Zaghloul 250g | U6: 10 | V6: =G6*$U6 -> 0 | W6: =H6*$U6 -> 780 | X6: =I6*$U6 -> 370 | Y6: =J6*$U6 -> 790 | Z6: =K6*$U6 -> 0 | AA6: =L6*$U6 -> 650 | AB6: =M6*$U6 -> 0 | AC6: =N6*$U6 -> 0 | ... AG6: =R6*$U6 -> 1400 | AH6: =SUM(V6:AG6) -> 5200 | AI6: Other Flavors | AJ6: =C6&" "&AI6&"" -> Nakhla Other Flavors | AK6: =S6 -> 520 | AL6: =AH6 -> 5200 | AM6: =AL6/$AL$185 -> 0.0012361136
A7: 4562 | B7: معسل أدخنة النخلة تفاحتين بحريني 50غ | C7: Nakhla | D7: Two Apple Bahraini | E7: 50g | F7: =C7&" "&D7&" "&E7 -> Nakhla Two Apple Bahraini 50g | G7: 1128 | H7: 5513 | I7: 8705 | J7: 1603 | L7: 2552 | M7: 74 | S7: =SUM(G7:R7) -> 19575 | T7: =F7 -> Nakhla Two Apple Bahraini 50g | U7: 10 | V7: =G7*$U7 -> 11280 | W7: =H7*$U7 -> 55130 | X7: =I7*$U7 -> 87050 | Y7: =J7*$U7 -> 16030 | Z7: =K7*$U7 -> 0 | AA7: =L7*$U7 -> 25520 | AB7: =M7*$U7 -> 740 | AC7: =N7*$U7 -> 0 | ... AG7: =R7*$U7 -> 0 | AH7: =SUM(V7:AG7) -> 195750 | AI7: Two Apple | AJ7: =C7&" "&AI7&"" -> Nakhla Two Apple | AK7: =S7 -> 19575 | AL7: =AH7 -> 195750 | AM7: =AL7/$AL$185 -> 0.046532547
A8: 4563 | B8: معسل أدخنة النخلة زغلول 50 غ | C8: Nakhla | D8: Zaghloul | E8: 50g | F8: =C8&" "&D8&" "&E8 -> Nakhla Zaghloul 50g | H8: 33 | I8: 54 | J8: 29 | L8: 58 | M8: 21 | N8: 5 | O8: 2 | Q8: 51 | R8: 331 | S8: =SUM(G8:R8) -> 584 | T8: =F8 -> Nakhla Zaghloul 50g | U8: 12.5 | V8: =G8*$U8 -> 0 | W8: =H8*$U8 -> 412.5 | X8: =I8*$U8 -> 675 | Y8: =J8*$U8 -> 362.5 | Z8: =K8*$U8 -> 0 | AA8: =L8*$U8 -> 725 | AB8: =M8*$U8 -> 262.5 | AC8: =N8*$U8 -> 62.5 | ... AG8: =R8*$U8 -> 4137.5 | AH8: =SUM(V8:AG8) -> 7300 | AI8: Other Flavors | AJ8: =C8&" "&AI8&"" -> Nakhla Other Flavors | AK8: =S8 -> 584 | AL8: =AH8 -> 7300 | AM8: =AL8/$AL$185 -> 0.0017353134
A9: 4738 | B9: الفاخر تفاحتين بحريني 250غ | C9: Al Fakher | D9: Two Apple Bahraini | E9: 250g | F9: =C9&" "&D9&" "&E9 -> Al Fakher Two Apple Bahraini 250g | H9: 175 | K9: 200 | M9: 613 | N9: 370 | S9: =SUM(G9:R9) -> 1358 | T9: =F9 -> Al Fakher Two Apple Bahraini 250g | U9: 6 | V9: =G9*$U9 -> 0 | W9: =H9*$U9 -> 1050 | X9: =I9*$U9 -> 0 | Y9: =J9*$U9 -> 0 | Z9: =K9*$U9 -> 1200 | AA9: =L9*$U9 -> 0 | AB9: =M9*$U9 -> 3678 | AC9: =N9*$U9 -> 2220 | ... AG9: =R9*$U9 -> 0 | AH9: =SUM(V9:AG9) -> 8148 | AI9: Two Apple | AJ9: =C9&" "&AI9&"" -> Al Fakher Two Apple | AK9: =S9 -> 1358 | AL9: =AH9 -> 8148 | AM9: =AL9/$AL$185 -> 0.001936895
A10: 4770 | B10: معسل الفاخر حامض ونعنع 50 غ | C10: Al Fakher | D10: Lemon Mint | E10: 50g | F10: =C10&" "&D10&" "&E10 -> Al Fakher Lemon Mint 50g | G10: 75 | I10: 663 | J10: 120 | K10: 292 | L10: 197 | M10: 189 | N10: 686 | O10: 220 | P10: 98 | Q10: 109 | S10: =SUM(G10:R10) -> 2649 | T10: =F10 -> Al Fakher Lemon Mint 50g | U10: 6 | V10: =G10*$U10 -> 450 | W10: =H10*$U10 -> 0 | X10: =I10*$U10 -> 3978 | Y10: =J10*$U10 -> 720 | Z10: =K10*$U10 -> 1752 | AA10: =L10*$U10 -> 1182 | AB10: =M10*$U10 -> 1134 | AC10: =N10*$U10 -> 4116 | ... AG10: =R10*$U10 -> 0 | AH10: =SUM(V10:AG10) -> 15894 | AI10: Lemon Mint | AJ10: =C10&" "&AI10&"" -> Al Fakher Lemon Mint | AK10: =S10 -> 2649 | AL10: =AH10 -> 15894 | AM10: =AL10/$AL$185 -> 0.0037782289
A11: 4771 | B11: معسل الفاخر عنب مع نعنع 50 غ | C11: Al Fakher | D11: Grapes Mint | E11: 50g | F11: =C11&" "&D11&" "&E11 -> Al Fakher Grapes Mint 50g | G11: 90 | H11: 160 | I11: 382 | J11: 94 | K11: 268 | L11: 155 | M11: 308 | N11: 168 | O11: 175 | P11: 25 | S11: =SUM(G11:R11) -> 1825 | T11: =F11 -> Al Fakher Grapes Mint 50g | U11: 6 | V11: =G11*$U11 -> 540 | W11: =H11*$U11 -> 960 | X11: =I11*$U11 -> 2292 | Y11: =J11*$U11 -> 564 | Z11: =K11*$U11 -> 1608 | AA11: =L11*$U11 -> 930 | AB11: =M11*$U11 -> 1848 | AC11: =N11*$U11 -> 1008 | ... AG11: =R11*$U11 -> 0 | AH11: =SUM(V11:AG11) -> 10950 | AI11: Grapes Mint | AJ11: =C11&" "&AI11&"" -> Al Fakher Grapes Mint | AK11: =S11 -> 1825 | AL11: =AH11 -> 10950 | AM11: =AL11/$AL$185 -> 0.00260297
A12: 4772 | B12: معسل الفاخر علكه 50 غ | C12: Al Fakher | D12: Gum | E12: 50g | F12: =C12&" "&D12&" "&E12 -> Al Fakher Gum 50g | H12: 50 | I12: 50 | K12: 76 | L12: 24 | M12: 58 | N12: 139 | O12: 17 | P12: 17 | Q12: 249 | S12: =SUM(G12:R12) -> 680 | T12: =F12 -> Al Fakher Gum 50g | U12: 6 | V12: =G12*$U12 -> 0 | W12: =H12*$U12 -> 300 | X12: =I12*$U12 -> 300 | Y12: =J12*$U12 -> 0 | Z12: =K12*$U12 -> 456 | AA12: =L12*$U12 -> 144 | AB12: =M12*$U12 -> 348 | AC12: =N12*$U12 -> 834 | ... AG12: =R12*$U12 -> 0 | AH12: =SUM(V12:AG12) -> 4080 | AI12: Gum | AJ12: =C12&" "&AI12&"" -> Al Fakher Gum | AK12: =S12 -> 680 | AL12: =AH12 -> 4080 | AM12: =AL12/$AL$185 -> 0.00096987377
A13: 4775 | B13: معسل الفاخر بطيخ 50 غ | C13: Al Fakher | D13: watermelon | E13: 50g | F13: =C13&" "&D13&" "&E13 -> Al Fakher watermelon 50g | H13: 50 | K13: 38 | L13: 12 | O13: 50 | S13: =SUM(G13:R13) -> 150 | T13: =F13 -> Al Fakher watermelon 50g | U13: 6 | V13: =G13*$U13 -> 0 | W13: =H13*$U13 -> 300 | X13: =I13*$U13 -> 0 | Y13: =J13*$U13 -> 0 | Z13: =K13*$U13 -> 228 | AA13: =L13*$U13 -> 72 | AB13: =M13*$U13 -> 0 | AC13: =N13*$U13 -> 0 | ... AG13: =R13*$U13 -> 0 | AH13: =SUM(V13:AG13) -> 900 | AI13: Other Flavors | AJ13: =C13&" "&AI13&"" -> Al Fakher Other Flavors | AK13: =S13 -> 150 | AL13: =AH13 -> 900 | AM13: =AL13/$AL$185 -> 0.00021394274
A14: 4777 | B14: معسل الفاخر حامض ونعنع 250غ | C14: Al Fakher | D14: Lemon Mint | E14: 250g | F14: =C14&" "&D14&" "&E14 -> Al Fakher Lemon Mint 250g | G14: 25 | H14: 116 | I14: 202 | J14: 73 | K14: 79 | L14: 40 | M14: 142 | N14: 83 | O14: 52 | P14: 34 | Q14: 64 | S14: =SUM(G14:R14) -> 910 | T14: =F14 -> Al Fakher Lemon Mint 250g | U14: 6 | V14: =G14*$U14 -> 150 | W14: =H14*$U14 -> 696 | X14: =I14*$U14 -> 1212 | Y14: =J14*$U14 -> 438 | Z14: =K14*$U14 -> 474 | AA14: =L14*$U14 -> 240 | AB14: =M14*$U14 -> 852 | AC14: =N14*$U14 -> 498 | ... AG14: =R14*$U14 -> 0 | AH14: =SUM(V14:AG14) -> 5460 | AI14: Lemon Mint | AJ14: =C14&" "&AI14&"" -> Al Fakher Lemon Mint | AK14: =S14 -> 910 | AL14: =AH14 -> 5460 | AM14: =AL14/$AL$185 -> 0.0012979193
A15: 4778 | B15: معسل الفاخر نعنع 250غ | C15: Al Fakher | D15: Mint | E15: 250g | F15: =C15&" "&D15&" "&E15 -> Al Fakher Mint 250g | G15: 35 | H15: 15 | I15: 120 | J15: 36 | K15: 71 | L15: 44 | M15: 78 | N15: 50 | S15: =SUM(G15:R15) -> 449 | T15: =F15 -> Al Fakher Mint 250g | U15: 6 | V15: =G15*$U15 -> 210 | W15: =H15*$U15 -> 90 | X15: =I15*$U15 -> 720 | Y15: =J15*$U15 -> 216 | Z15: =K15*$U15 -> 426 | AA15: =L15*$U15 -> 264 | AB15: =M15*$U15 -> 468 | AC15: =N15*$U15 -> 300 | ... AG15: =R15*$U15 -> 0 | AH15: =SUM(V15:AG15) -> 2694 | AI15: Mint | AJ15: =C15&" "&AI15&"" -> Al Fakher Mint | AK15: =S15 -> 449 | AL15: =AH15 -> 2694 | AM15: =AL15/$AL$185 -> 0.00064040195
A16: 4779 | B16: معسل الفاخر علكة ونعنع 50غ | C16: Al Fakher | D16: Gum Mint | E16: 50g | F16: =C16&" "&D16&" "&E16 -> Al Fakher Gum Mint 50g | G16: 26 | H16: 50 | K16: 77 | L16: 42 | M16: 60 | N16: 164 | O16: 25 | P16: 6 | Q16: 76 | S16: =SUM(G16:R16) -> 526 | T16: =F16 -> Al Fakher Gum Mint 50g | U16: 6 | V16: =G16*$U16 -> 156 | W16: =H16*$U16 -> 300 | X16: =I16*$U16 -> 0 | Y16: =J16*$U16 -> 0 | Z16: =K16*$U16 -> 462 | AA16: =L16*$U16 -> 252 | AB16: =M16*$U16 -> 360 | AC16: =N16*$U16 -> 984 | ... AG16: =R16*$U16 -> 0 | AH16: =SUM(V16:AG16) -> 3156 | AI16: Gum | AJ16: =C16&" "&AI16&"" -> Al Fakher Gum | AK16: =S16 -> 526 | AL16: =AH16 -> 3156 | AM16: =AL16/$AL$185 -> 0.00075022589
A17: 4780 | B17: معسل الفاخر عنب ونعنع 250غ | C17: Al Fakher | D17: Grapes Mint | E17: 250g | F17: =C17&" "&D17&" "&E17 -> Al Fakher Grapes Mint 250g | G17: 109 | H17: 67 | J17: 48 | K17: 102 | O17: 50 | S17: =SUM(G17:R17) -> 376 | T17: =F17 -> Al Fakher Grapes Mint 250g | U17: 6 | V17: =G17*$U17 -> 654 | W17: =H17*$U17 -> 402 | X17: =I17*$U17 -> 0 | Y17: =J17*$U17 -> 288 | Z17: =K17*$U17 -> 612 | AA17: =L17*$U17 -> 0 | AB17: =M17*$U17 -> 0 | AC17: =N17*$U17 -> 0 | ... AG17: =R17*$U17 -> 0 | AH17: =SUM(V17:AG17) -> 2256 | AI17: Grapes Mint | AJ17: =C17&" "&AI17&"" -> Al Fakher Grapes Mint | AK17: =S17 -> 376 | AL17: =AH17 -> 2256 | AM17: =AL17/$AL$185 -> 0.00053628314
A18: 4782 | B18: معسل الفاخر خامض 250غ | C18: Al Fakher | D18: Lemon | E18: 250g | F18: =C18&" "&D18&" "&E18 -> Al Fakher Lemon 250g | S18: =SUM(G18:R18) -> 0 | T18: =F18 -> Al Fakher Lemon 250g | U18: 6 | V18: =G18*$U18 -> 0 | W18: =H18*$U18 -> 0 | X18: =I18*$U18 -> 0 | Y18: =J18*$U18 -> 0 | Z18: =K18*$U18 -> 0 | AA18: =L18*$U18 -> 0 | AB18: =M18*$U18 -> 0 | AC18: =N18*$U18 -> 0 | ... AG18: =R18*$U18 -> 0 | AH18: =SUM(V18:AG18) -> 0 | AI18: Other Flavors | AJ18: =C18&" "&AI18&"" -> Al Fakher Other Flavors | AK18: =S18 -> 0 | AL18: =AH18 -> 0 | AM18: =AL18/$AL$185 -> 0
A19: 4783 | B19: معسل الفاخر اورانج مع نعنع 250غ | C19: Al Fakher | D19: Orange & Mint | E19: 250g | F19: =C19&" "&D19&" "&E19 -> Al Fakher Orange & Mint 250g | K19: 10 | L19: 7 | M19: 7 | N19: 6 | S19: =SUM(G19:R19) -> 30 | T19: =F19 -> Al Fakher Orange & Mint 250g | U19: 6 | V19: =G19*$U19 -> 0 | W19: =H19*$U19 -> 0 | X19: =I19*$U19 -> 0 | Y19: =J19*$U19 -> 0 | Z19: =K19*$U19 -> 60 | AA19: =L19*$U19 -> 42 | AB19: =M19*$U19 -> 42 | AC19: =N19*$U19 -> 36 | ... AG19: =R19*$U19 -> 0 | AH19: =SUM(V19:AG19) -> 180 | AI19: Other Flavors | AJ19: =C19&" "&AI19&"" -> Al Fakher Other Flavors | AK19: =S19 -> 30 | AL19: =AH19 -> 180 | AM19: =AL19/$AL$185 -> 4.2788549e-05
A20: 4784 | B20: معسل الفاخر اورانج 250غ | C20: Al Fakher | D20: Orange | E20: 250g | F20: =C20&" "&D20&" "&E20 -> Al Fakher Orange 250g | K20: 10 | L20: 2 | M20: 10 | N20: 8 | S20: =SUM(G20:R20) -> 30 | T20: =F20 -> Al Fakher Orange 250g | U20: 6 | V20: =G20*$U20 -> 0 | W20: =H20*$U20 -> 0 | X20: =I20*$U20 -> 0 | Y20: =J20*$U20 -> 0 | Z20: =K20*$U20 -> 60 | AA20: =L20*$U20 -> 12 | AB20: =M20*$U20 -> 60 | AC20: =N20*$U20 -> 48 | ... AG20: =R20*$U20 -> 0 | AH20: =SUM(V20:AG20) -> 180 | AI20: Other Flavors | AJ20: =C20&" "&AI20&"" -> Al Fakher Other Flavors | AK20: =S20 -> 30 | AL20: =AH20 -> 180 | AM20: =AL20/$AL$185 -> 4.2788549e-05
A21: 4786 | B21: معسل الفاخرعنب مع توت 250غ | C21: Al Fakher | D21: Grape & Berry | E21: 50g | F21: =C21&" "&D21&" "&E21 -> Al Fakher Grape & Berry 50g | K21: 42 | L21: 8 | S21: =SUM(G21:R21) -> 50 | T21: =F21 -> Al Fakher Grape & Berry 50g | U21: 6 | V21: =G21*$U21 -> 0 | W21: =H21*$U21 -> 0 | X21: =I21*$U21 -> 0 | Y21: =J21*$U21 -> 0 | Z21: =K21*$U21 -> 252 | AA21: =L21*$U21 -> 48 | AB21: =M21*$U21 -> 0 | AC21: =N21*$U21 -> 0 | ... AG21: =R21*$U21 -> 0 | AH21: =SUM(V21:AG21) -> 300 | AI21: Other Flavors | AJ21: =C21&" "&AI21&"" -> Al Fakher Other Flavors | AK21: =S21 -> 50 | AL21: =AH21 -> 300 | AM21: =AL21/$AL$185 -> 7.1314248e-05
A22: 4791 | B22: معسل الفاخرتفاحتين مع نعنع 50غ | C22: Al Fakher | D22: Two Apple & Minit | E22: 50g | F22: =C22&" "&D22&" "&E22 -> Al Fakher Two Apple & Minit 50g | K22: 27 | L22: 23 | S22: =SUM(G22:R22) -> 50 | T22: =F22 -> Al Fakher Two Apple & Minit 50g | U22: 6 | V22: =G22*$U22 -> 0 | W22: =H22*$U22 -> 0 | X22: =I22*$U22 -> 0 | Y22: =J22*$U22 -> 0 | Z22: =K22*$U22 -> 162 | AA22: =L22*$U22 -> 138 | AB22: =M22*$U22 -> 0 | AC22: =N22*$U22 -> 0 | ... AG22: =R22*$U22 -> 0 | AH22: =SUM(V22:AG22) -> 300 | AI22: Two Apple | AJ22: =C22&" "&AI22&"" -> Al Fakher Two Apple | AK22: =S22 -> 50 | AL22: =AH22 -> 300 | AM22: =AL22/$AL$185 -> 7.1314248e-05
A23: 4792 | B23: معسل الفاخر ببل جام 50غ | C23: Al Fakher | D23: Bubble Gum | E23: 50g | F23: =C23&" "&D23&" "&E23 -> Al Fakher Bubble Gum 50g | H23: 49 | I23: 20 | K23: 27 | L23: 6 | M23: 12 | N23: 105 | O23: 22 | P23: 1 | Q23: 27 | S23: =SUM(G23:R23) -> 269 | T23: =F23 -> Al Fakher Bubble Gum 50g | U23: 6 | V23: =G23*$U23 -> 0 | W23: =H23*$U23 -> 294 | X23: =I23*$U23 -> 120 | Y23: =J23*$U23 -> 0 | Z23: =K23*$U23 -> 162 | AA23: =L23*$U23 -> 36 | AB23: =M23*$U23 -> 72 | AC23: =N23*$U23 -> 630 | ... AG23: =R23*$U23 -> 0 | AH23: =SUM(V23:AG23) -> 1614 | AI23: Gum | AJ23: =C23&" "&AI23&"" -> Al Fakher Gum | AK23: =S23 -> 269 | AL23: =AH23 -> 1614 | AM23: =AL23/$AL$185 -> 0.00038367065
A24: 4793 | B24: معسل الفاخر مانجا 50غ | C24: Al Fakher | D24: Mango | E24: 50g | F24: =C24&" "&D24&" "&E24 -> Al Fakher Mango 50g | K24: 43 | L24: 7 | S24: =SUM(G24:R24) -> 50 | T24: =F24 -> Al Fakher Mango 50g | U24: 6 | V24: =G24*$U24 -> 0 | W24: =H24*$U24 -> 0 | X24: =I24*$U24 -> 0 | Y24: =J24*$U24 -> 0 | Z24: =K24*$U24 -> 258 | AA24: =L24*$U24 -> 42 | AB24: =M24*$U24 -> 0 | AC24: =N24*$U24 -> 0 | ... AG24: =R24*$U24 -> 0 | AH24: =SUM(V24:AG24) -> 300 | AI24: Other Flavors | AJ24: =C24&" "&AI24&"" -> Al Fakher Other Flavors | AK24: =S24 -> 50 | AL24: =AH24 -> 300 | AM24: =AL24/$AL$185 -> 7.1314248e-05
A25: 4794 | B25: معسل الفاخر علكه مستكه 50غ | C25: Al Fakher | D25: Gum Mastic | E25: 50g | F25: =C25&" "&D25&" "&E25 -> Al Fakher Gum Mastic 50g | I25: 50 | K25: 51 | L25: 13 | M25: 8 | N25: 78 | O25: 11 | P25: 6 | Q25: 133 | S25: =SUM(G25:R25) -> 350 | T25: =F25 -> Al Fakher Gum Mastic 50g | U25: 6 | V25: =G25*$U25 -> 0 | W25: =H25*$U25 -> 0 | X25: =I25*$U25 -> 300 | Y25: =J25*$U25 -> 0 | Z25: =K25*$U25 -> 306 | AA25: =L25*$U25 -> 78 | AB25: =M25*$U25 -> 48 | AC25: =N25*$U25 -> 468 | ... AG25: =R25*$U25 -> 0 | AH25: =SUM(V25:AG25) -> 2100 | AI25: Gum | AJ25: =C25&" "&AI25&"" -> Al Fakher Gum | AK25: =S25 -> 350 | AL25: =AH25 -> 2100 | AM25: =AL25/$AL$185 -> 0.00049919974
A26: 4796 | B26: معسل الفاخر برتقال مع نعنع 50غ | C26: Al Fakher | D26: Orange & Mint | E26: 50g | F26: =C26&" "&D26&" "&E26 -> Al Fakher Orange & Mint 50g | K26: 50 | M26: 5 | N26: 47 | O26: 47 | P26: 1 | Q26: 2 | S26: =SUM(G26:R26) -> 152 | T26: =F26 -> Al Fakher Orange & Mint 50g | U26: 6 | V26: =G26*$U26 -> 0 | W26: =H26*$U26 -> 0 | X26: =I26*$U26 -> 0 | Y26: =J26*$U26 -> 0 | Z26: =K26*$U26 -> 300 | AA26: =L26*$U26 -> 0 | AB26: =M26*$U26 -> 30 | AC26: =N26*$U26 -> 282 | ... AG26: =R26*$U26 -> 0 | AH26: =SUM(V26:AG26) -> 912 | AI26: Other Flavors | AJ26: =C26&" "&AI26&"" -> Al Fakher Other Flavors | AK26: =S26 -> 152 | AL26: =AH26 -> 912 | AM26: =AL26/$AL$185 -> 0.00021679531
A27: 4797 | B27: معسل الفاخر بطيخ مع نعنع 50غ | C27: Al Fakher | D27: Watermelon & Mint | E27: 50g | F27: =C27&" "&D27&" "&E27 -> Al Fakher Watermelon & Mint 50g | G27: 10 | K27: 24 | L27: 12 | M27: 10 | N27: 4 | O27: 50 | S27: =SUM(G27:R27) -> 110 | T27: =F27 -> Al Fakher Watermelon & Mint 50g | U27: 6 | V27: =G27*$U27 -> 60 | W27: =H27*$U27 -> 0 | X27: =I27*$U27 -> 0 | Y27: =J27*$U27 -> 0 | Z27: =K27*$U27 -> 144 | AA27: =L27*$U27 -> 72 | AB27: =M27*$U27 -> 60 | AC27: =N27*$U27 -> 24 | ... AG27: =R27*$U27 -> 0 | AH27: =SUM(V27:AG27) -> 660 | AI27: Other Flavors | AJ27: =C27&" "&AI27&"" -> Al Fakher Other Flavors | AK27: =S27 -> 110 | AL27: =AH27 -> 660 | AM27: =AL27/$AL$185 -> 0.00015689135
A28: 4809 | B28: الفاخر بلوبيري 250غ | C28: Al Fakher | D28: Blueberry | E28: 250g | F28: =C28&" "&D28&" "&E28 -> Al Fakher Blueberry 250g | G28: 3 | H28: 10 | I28: 51 | J28: 9 | K28: 11 | L28: 24 | M28: 20 | N28: 12 | S28: =SUM(G28:R28) -> 140 | T28: =F28 -> Al Fakher Blueberry 250g | U28: 6 | V28: =G28*$U28 -> 18 | W28: =H28*$U28 -> 60 | X28: =I28*$U28 -> 306 | Y28: =J28*$U28 -> 54 | Z28: =K28*$U28 -> 66 | AA28: =L28*$U28 -> 144 | AB28: =M28*$U28 -> 120 | AC28: =N28*$U28 -> 72 | ... AG28: =R28*$U28 -> 0 | AH28: =SUM(V28:AG28) -> 840 | AI28: Other Flavors | AJ28: =C28&" "&AI28&"" -> Al Fakher Other Flavors | AK28: =S28 -> 140 | AL28: =AH28 -> 840 | AM28: =AL28/$AL$185 -> 0.00019967989
A29: 4816 | B29: نخله بلوبيري 50 غ | C29: Nakhla | D29: Blueberry | E29: 50g | F29: =C29&" "&D29&" "&E29 -> Nakhla Blueberry 50g | H29: 75 | I29: 25 | L29: 5 | N29: 5 | S29: =SUM(G29:R29) -> 110 | T29: =F29 -> Nakhla Blueberry 50g | U29: 12.5 | V29: =G29*$U29 -> 0 | W29: =H29*$U29 -> 937.5 | X29: =I29*$U29 -> 312.5 | Y29: =J29*$U29 -> 0 | Z29: =K29*$U29 -> 0 | AA29: =L29*$U29 -> 62.5 | AB29: =M29*$U29 -> 0 | AC29: =N29*$U29 -> 62.5 | ... AG29: =R29*$U29 -> 0 | AH29: =SUM(V29:AG29) -> 1375 | AI29: Other Flavors | AJ29: =C29&" "&AI29&"" -> Nakhla Other Flavors | AK29: =S29 -> 110 | AL29: =AH29 -> 1375 | AM29: =AL29/$AL$185 -> 0.00032685697
A30: 4820 | B30: نخلة دراق 50غ | C30: Nakhla | D30: Blueberry | E30: 50g | F30: =C30&" "&D30&" "&E30 -> Nakhla Blueberry 50g | G30: 3 | H30: 80 | I30: 26 | N30: 9 | S30: =SUM(G30:R30) -> 118 | T30: =F30 -> Nakhla Blueberry 50g | U30: 12.5 | V30: =G30*$U30 -> 37.5 | W30: =H30*$U30 -> 1000 | X30: =I30*$U30 -> 325 | Y30: =J30*$U30 -> 0 | Z30: =K30*$U30 -> 0 | AA30: =L30*$U30 -> 0 | AB30: =M30*$U30 -> 0 | AC30: =N30*$U30 -> 112.5 | ... AG30: =R30*$U30 -> 0 | AH30: =SUM(V30:AG30) -> 1475 | AI30: Other Flavors | AJ30: =C30&" "&AI30&"" -> Nakhla Other Flavors | AK30: =S30 -> 118 | AL30: =AH30 -> 1475 | AM30: =AL30/$AL$185 -> 0.00035062839
A31: 4828 | B31: الفاخر تفاحتين بحريني 50غ | C31: Al Fakher | D31: Two Apple Bahraini | E31: 250g | F31: =C31&" "&D31&" "&E31 -> Al Fakher Two Apple Bahraini 250g | K31: 650 | L31: 175 | S31: =SUM(G31:R31) -> 825 | T31: =F31 -> Al Fakher Two Apple Bahraini 250g | U31: 6 | V31: =G31*$U31 -> 0 | W31: =H31*$U31 -> 0 | X31: =I31*$U31 -> 0 | Y31: =J31*$U31 -> 0 | Z31: =K31*$U31 -> 3900 | AA31: =L31*$U31 -> 1050 | AB31: =M31*$U31 -> 0 | AC31: =N31*$U31 -> 0 | ... AG31: =R31*$U31 -> 0 | AH31: =SUM(V31:AG31) -> 4950 | AI31: Two Apple | AJ31: =C31&" "&AI31&"" -> Al Fakher Two Apple | AK31: =S31 -> 825 | AL31: =AH31 -> 4950 | AM31: =AL31/$AL$185 -> 0.0011766851
A32: 4829 | B32: الفاخر بلوبيريي مع نعنع 50غ | C32: Al Fakher | D32: Blueberry Mint | E32: 50g | F32: =C32&" "&D32&" "&E32 -> Al Fakher Blueberry Mint 50g | K32: 64 | L32: 28 | M32: 27 | N32: 73 | O32: 15 | P32: 7 | Q32: 96 | S32: =SUM(G32:R32) -> 310 | T32: =F32 -> Al Fakher Blueberry Mint 50g | U32: 6 | V32: =G32*$U32 -> 0 | W32: =H32*$U32 -> 0 | X32: =I32*$U32 -> 0 | Y32: =J32*$U32 -> 0 | Z32: =K32*$U32 -> 384 | AA32: =L32*$U32 -> 168 | AB32: =M32*$U32 -> 162 | AC32: =N32*$U32 -> 438 | ... AG32: =R32*$U32 -> 0 | AH32: =SUM(V32:AG32) -> 1860 | AI32: Other Flavors | AJ32: =C32&" "&AI32&"" -> Al Fakher Other Flavors | AK32: =S32 -> 310 | AL32: =AH32 -> 1860 | AM32: =AL32/$AL$185 -> 0.00044214834
A33: 4885 | B33: الفاخر نعنع 1 كلغ | C33: Al Fakher | D33: Mint | E33: 1kg | F33: =C33&" "&D33&" "&E33 -> Al Fakher Mint 1kg | G33: 125 | H33: 325 | I33: 660 | J33: 151 | K33: 324 | L33: 541 | M33: 461 | N33: 739 | O33: 218 | P33: 82 | S33: =SUM(G33:R33) -> 3626 | T33: =F33 -> Al Fakher Mint 1kg | U33: 6 | V33: =G33*$U33 -> 750 | W33: =H33*$U33 -> 1950 | X33: =I33*$U33 -> 3960 | Y33: =J33*$U33 -> 906 | Z33: =K33*$U33 -> 1944 | AA33: =L33*$U33 -> 3246 | AB33: =M33*$U33 -> 2766 | AC33: =N33*$U33 -> 4434 | ... AG33: =R33*$U33 -> 0 | AH33: =SUM(V33:AG33) -> 21756 | AI33: Mint | AJ33: =C33&" "&AI33&"" -> Al Fakher Mint | AK33: =S33 -> 3626 | AL33: =AH33 -> 21756 | AM33: =AL33/$AL$185 -> 0.0051717093
A34: 4886 | B34: الفاخر عنب مع نعنع 1كلغ | C34: Al Fakher | D34: Grapes Mint | E34: 1kg | F34: =C34&" "&D34&" "&E34 -> Al Fakher Grapes Mint 1kg | G34: 50 | J34: 150 | K34: 150 | L34: 200 | M34: 400 | O34: 150 | S34: =SUM(G34:R34) -> 1100 | T34: =F34 -> Al Fakher Grapes Mint 1kg | U34: 6 | V34: =G34*$U34 -> 300 | W34: =H34*$U34 -> 0 | X34: =I34*$U34 -> 0 | Y34: =J34*$U34 -> 900 | Z34: =K34*$U34 -> 900 | AA34: =L34*$U34 -> 1200 | AB34: =M34*$U34 -> 2400 | AC34: =N34*$U34 -> 0 | ... AG34: =R34*$U34 -> 0 | AH34: =SUM(V34:AG34) -> 6600 | AI34: Grapes Mint | AJ34: =C34&" "&AI34&"" -> Al Fakher Grapes Mint | AK34: =S34 -> 1100 | AL34: =AH34 -> 6600 | AM34: =AL34/$AL$185 -> 0.0015689135
A35: 4887 | B35: الفاخر حامض ونعنع 1كلغ | C35: Al Fakher | D35: Lemon Mint | E35: 1kg | F35: =C35&" "&D35&" "&E35 -> Al Fakher Lemon Mint 1kg | G35: 175 | H35: 325 | I35: 1167 | J35: 272 | K35: 410 | L35: 348 | M35: 413 | N35: 932 | O35: 291 | P35: 109 | S35: =SUM(G35:R35) -> 4442 | T35: =F35 -> Al Fakher Lemon Mint 1kg | U35: 6 | V35: =G35*$U35 -> 1050 | W35: =H35*$U35 -> 1950 | X35: =I35*$U35 -> 7002 | Y35: =J35*$U35 -> 1632 | Z35: =K35*$U35 -> 2460 | AA35: =L35*$U35 -> 2088 | AB35: =M35*$U35 -> 2478 | AC35: =N35*$U35 -> 5592 | ... AG35: =R35*$U35 -> 0 | AH35: =SUM(V35:AG35) -> 26652 | AI35: Lemon Mint | AJ35: =C35&" "&AI35&"" -> Al Fakher Lemon Mint | AK35: =S35 -> 4442 | AL35: =AH35 -> 26652 | AM35: =AL35/$AL$185 -> 0.0063355578
A36: 4888 | B36: الفاخر عنب 1كلغ | C36: Al Fakher | D36: Grapes | E36: 1kg | F36: =C36&" "&D36&" "&E36 -> Al Fakher Grapes 1kg | G36: 324 | H36: 476 | I36: 1277 | J36: 381 | K36: 431 | L36: 482 | M36: 491 | N36: 1035 | O36: 359 | P36: 41 | S36: =SUM(G36:R36) -> 5297 | T36: =F36 -> Al Fakher Grapes 1kg | U36: 6 | V36: =G36*$U36 -> 1944 | W36: =H36*$U36 -> 2856 | X36: =I36*$U36 -> 7662 | Y36: =J36*$U36 -> 2286 | Z36: =K36*$U36 -> 2586 | AA36: =L36*$U36 -> 2892 | AB36: =M36*$U36 -> 2946 | AC36: =N36*$U36 -> 6210 | ... AG36: =R36*$U36 -> 0 | AH36: =SUM(V36:AG36) -> 31782 | AI36: Grapes | AJ36: =C36&" "&AI36&"" -> Al Fakher Grapes | AK36: =S36 -> 5297 | AL36: =AH36 -> 31782 | AM36: =AL36/$AL$185 -> 0.0075550314
A37: 4890 | B37: الفاخر برتقال 1 كلغ | C37: Al Fakher | D37: Orange | E37: 1kg | F37: =C37&" "&D37&" "&E37 -> Al Fakher Orange 1kg | K37: 50 | M37: 77 | N37: 23 | O37: 50 | S37: =SUM(G37:R37) -> 200 | T37: =F37 -> Al Fakher Orange 1kg | U37: 6 | V37: =G37*$U37 -> 0 | W37: =H37*$U37 -> 0 | X37: =I37*$U37 -> 0 | Y37: =J37*$U37 -> 0 | Z37: =K37*$U37 -> 300 | AA37: =L37*$U37 -> 0 | AB37: =M37*$U37 -> 462 | AC37: =N37*$U37 -> 138 | ... AG37: =R37*$U37 -> 0 | AH37: =SUM(V37:AG37) -> 1200 | AI37: Other Flavors | AJ37: =C37&" "&AI37&"" -> Al Fakher Other Flavors | AK37: =S37 -> 200 | AL37: =AH37 -> 1200 | AM37: =AL37/$AL$185 -> 0.00028525699
A38: 4891 | B38: الفاخرخامض 1 كلغ | C38: Al Fakher | D38: Lemon | E38: 1kg | F38: =C38&" "&D38&" "&E38 -> Al Fakher Lemon 1kg | S38: =SUM(G38:R38) -> 0 | T38: =F38 -> Al Fakher Lemon 1kg | U38: 6 | V38: =G38*$U38 -> 0 | W38: =H38*$U38 -> 0 | X38: =I38*$U38 -> 0 | Y38: =J38*$U38 -> 0 | Z38: =K38*$U38 -> 0 | AA38: =L38*$U38 -> 0 | AB38: =M38*$U38 -> 0 | AC38: =N38*$U38 -> 0 | ... AG38: =R38*$U38 -> 0 | AH38: =SUM(V38:AG38) -> 0 | AI38: Other Flavors | AJ38: =C38&" "&AI38&"" -> Al Fakher Other Flavors | AK38: =S38 -> 0 | AL38: =AH38 -> 0 | AM38: =AL38/$AL$185 -> 0
A39: 4892 | B39: الفاخر تفاحتين 1 كلغ | C39: Al Fakher | D39: Two Apple | E39: 1kg | F39: =C39&" "&D39&" "&E39 -> Al Fakher Two Apple 1kg | G39: 550 | H39: 1390 | I39: 3323 | J39: 1267 | K39: 1390 | L39: 965 | M39: 2133 | N39: 767 | O39: 2056 | P39: 2643 | Q39: 2441 | S39: =SUM(G39:R39) -> 18925 | T39: =F39 -> Al Fakher Two Apple 1kg | U39: 6 | V39: =G39*$U39 -> 3300 | W39: =H39*$U39 -> 8340 | X39: =I39*$U39 -> 19938 | Y39: =J39*$U39 -> 7602 | Z39: =K39*$U39 -> 8340 | AA39: =L39*$U39 -> 5790 | AB39: =M39*$U39 -> 12798 | AC39: =N39*$U39 -> 4602 | ... AG39: =R39*$U39 -> 0 | AH39: =SUM(V39:AG39) -> 113550 | AI39: Two Apple | AJ39: =C39&" "&AI39&"" -> Al Fakher Two Apple | AK39: =S39 -> 18925 | AL39: =AH39 -> 113550 | AM39: =AL39/$AL$185 -> 0.026992443
A40: 4893 | B40: الفاخر مانغا 1 كلغ | C40: Al Fakher | D40: Mango | E40: 1kg | F40: =C40&" "&D40&" "&E40 -> Al Fakher Mango 1kg | S40: =SUM(G40:R40) -> 0 | T40: =F40 -> Al Fakher Mango 1kg | U40: 6 | V40: =G40*$U40 -> 0 | W40: =H40*$U40 -> 0 | X40: =I40*$U40 -> 0 | Y40: =J40*$U40 -> 0 | Z40: =K40*$U40 -> 0 | AA40: =L40*$U40 -> 0 | AB40: =M40*$U40 -> 0 | AC40: =N40*$U40 -> 0 | ... AG40: =R40*$U40 -> 0 | AH40: =SUM(V40:AG40) -> 0 | AI40: Other Flavors | AJ40: =C40&" "&AI40&"" -> Al Fakher Other Flavors | AK40: =S40 -> 0 | AL40: =AH40 -> 0 | AM40: =AL40/$AL$185 -> 0
...

Sheet Regie Sales 2023
A1: Item | B1: Supplier | C1: Flavor | D1: Format | E1: SKU | F1: Jan | G1: Feb | H1: March | I1: Apr | J1: May | K1: June | L1: July | M1: Aug | N1: Sep | O1: Oct | P1: Nov | Q1: Dec | R1: Total | S1: SKU | T1: Weight/MasterCase | U1: Jan | V1: Feb | W1: March | X1: Apr | Y1: May | Z1: June | AA1: July | AB1: Aug | AC1: Sep | AD1: Oct | AE1: Nov | AF1: Dec | AG1: Total | AH1: Flavors | AI1: Flavors | AJ1: MasterCase | AK1: KG | AL1: Share KG %
A2: 6111 | B2: Al Basha | C2: Two Apple | D2: 250g | E2: Basha Two Apple 250g | F2: 381 | G2: 244 | H2: 276 | I2: 133 | J2: 170 | K2: 23 | L2: 78 | N2: 428 | O2: 87 | P2: 0 | Q2: 90 | R2: =SUM(F2:Q2) -> 1910 | S2: =E2 -> Basha Two Apple 250g | T2: 10 | U2: =F2*$T2 -> 3810 | V2: =G2*$T2 -> 2440 | W2: =H2*$T2 -> 2760 | X2: =I2*$T2 -> 1330 | Y2: =J2*$T2 -> 1700 | Z2: =K2*$T2 -> 230 | AA2: =L2*$T2 -> 780 | AB2: =M2*$T2 -> 0 | ... AF2: =Q2*$T2 -> 900 | AG2: =SUM(U2:AF2) -> 19100 | AH2: Two Apple | AI2: =B2&" "&AH2&"" -> Al Basha Two Apple | AJ2: =R2 -> 1910 | AK2: =AG2 -> 19100 | AL2: =AG2/$AG$126 -> 0.0042350262
A3: 6113 | B3: Al Basha | C3: Lemon Mint | D3: 250g | E3: Basha Two Apple 250g | K3: 400 | L3: 51 | N3: 151 | O3: 127 | P3: 150 | Q3: 310 | R3: =SUM(F3:Q3) -> 1189 | S3: =E3 -> Basha Two Apple 250g | T3: 10 | U3: =F3*$T3 -> 0 | V3: =G3*$T3 -> 0 | W3: =H3*$T3 -> 0 | X3: =I3*$T3 -> 0 | Y3: =J3*$T3 -> 0 | Z3: =K3*$T3 -> 4000 | AA3: =L3*$T3 -> 510 | AB3: =M3*$T3 -> 0 | ... AF3: =Q3*$T3 -> 3100 | AG3: =SUM(U3:AF3) -> 11890 | AH3: Lemon Mint | AI3: =B3&" "&AH3&"" -> Al Basha Lemon Mint | AJ3: =R3 -> 1189 | AK3: =AG3 -> 11890 | AL3: =AG3/$AG$126 -> 0.0026363593
A4: 6112 | B4: Al Basha | C4: Two Apple | D4: 1kg | E4: Basha Two Apple 1000g | F4: 343 | G4: 201 | H4: 44 | I4: 45 | J4: 160 | K4: 33 | L4: 142 | N4: 125 | O4: 80 | P4: 0 | Q4: 150 | R4: =SUM(F4:Q4) -> 1323 | S4: =E4 -> Basha Two Apple 1000g | T4: 10 | U4: =F4*$T4 -> 3430 | V4: =G4*$T4 -> 2010 | W4: =H4*$T4 -> 440 | X4: =I4*$T4 -> 450 | Y4: =J4*$T4 -> 1600 | Z4: =K4*$T4 -> 330 | AA4: =L4*$T4 -> 1420 | AB4: =M4*$T4 -> 0 | ... AF4: =Q4*$T4 -> 1500 | AG4: =SUM(U4:AF4) -> 13230 | AH4: Two Apple | AI4: =B4&" "&AH4&"" -> Al Basha Two Apple | AJ4: =R4 -> 1323 | AK4: =AG4 -> 13230 | AL4: =AG4/$AG$126 -> 0.0029334763
A5: 6120 | B5: Al Fakher | C5: Grape Mint | D5: 1kg | E5: =B5&" "&C5&" "&D5 -> Al Fakher Grape Mint 1kg | F5: 121 | J5: 841 | K5: 233 | L5: 499 | M5: 348 | N5: 594 | O5: 596 | P5: 250 | Q5: 306 | R5: =SUM(F5:Q5) -> 3788 | S5: =E5 -> Al Fakher Grape Mint 1kg | T5: 6 | U5: =F5*$T5 -> 726 | V5: =G5*$T5 -> 0 | W5: =H5*$T5 -> 0 | X5: =I5*$T5 -> 0 | Y5: =J5*$T5 -> 5046 | Z5: =K5*$T5 -> 1398 | AA5: =L5*$T5 -> 2994 | AB5: =M5*$T5 -> 2088 | ... AF5: =Q5*$T5 -> 1836 | AG5: =SUM(U5:AF5) -> 22728 | AH5: Grape Mint | AI5: =B5&" "&AH5&"" -> Al Fakher Grape Mint | AJ5: =R5 -> 3788 | AK5: =AG5 -> 22728 | AL5: =AG5/$AG$126 -> 0.0050394595
A6: 6121 | B6: Al Fakher | C6: Grapes | D6: 1kg | E6: =B6&" "&C6&" "&D6 -> Al Fakher Grapes 1kg | F6: 229 | J6: 926 | K6: 0 | L6: 934 | M6: 542 | N6: 367 | O6: 0 | P6: 0 | Q6: 0 | R6: =SUM(F6:Q6) -> 2998 | S6: =E6 -> Al Fakher Grapes 1kg | T6: 6 | U6: =F6*$T6 -> 1374 | V6: =G6*$T6 -> 0 | W6: =H6*$T6 -> 0 | X6: =I6*$T6 -> 0 | Y6: =J6*$T6 -> 5556 | Z6: =K6*$T6 -> 0 | AA6: =L6*$T6 -> 5604 | AB6: =M6*$T6 -> 3252 | ... AF6: =Q6*$T6 -> 0 | AG6: =SUM(U6:AF6) -> 17988 | AH6: Grapes | AI6: =B6&" "&AH6&"" -> Al Fakher Grapes | AJ6: =R6 -> 2998 | AK6: =AG6 -> 17988 | AL6: =AG6/$AG$126 -> 0.0039884634
A7: 6122 | B7: Al Fakher | C7: Lemon Mint | D7: 1kg | E7: =B7&" "&C7&" "&D7 -> Al Fakher Lemon Mint 1kg | F7: 298 | G7: 339 | H7: 87 | I7: 82 | J7: 67 | K7: 90 | L7: 285 | M7: 220 | N7: 406 | O7: 350 | P7: 376 | Q7: 354 | R7: =SUM(F7:Q7) -> 2954 | S7: =E7 -> Al Fakher Lemon Mint 1kg | T7: 6 | U7: =F7*$T7 -> 1788 | V7: =G7*$T7 -> 2034 | W7: =H7*$T7 -> 522 | X7: =I7*$T7 -> 492 | Y7: =J7*$T7 -> 402 | Z7: =K7*$T7 -> 540 | AA7: =L7*$T7 -> 1710 | AB7: =M7*$T7 -> 1320 | ... AF7: =Q7*$T7 -> 2124 | AG7: =SUM(U7:AF7) -> 17724 | AH7: Lemon Mint | AI7: =B7&" "&AH7&"" -> Al Fakher Lemon Mint | AJ7: =R7 -> 2954 | AK7: =AG7 -> 17724 | AL7: =AG7/$AG$126 -> 0.0039299269
A8: 6123 | B8: Al Fakher | C8: Mint | D8: 1kg | E8: =B8&" "&C8&" "&D8 -> Al Fakher Mint 1kg | F8: 406 | G8: 260 | J8: 470 | K8: 110 | L8: 571 | M8: 236 | N8: 417 | O8: 190 | P8: 60 | Q8: 82 | R8: =SUM(F8:Q8) -> 2802 | S8: =E8 -> Al Fakher Mint 1kg | T8: 6 | U8: =F8*$T8 -> 2436 | V8: =G8*$T8 -> 1560 | W8: =H8*$T8 -> 0 | X8: =I8*$T8 -> 0 | Y8: =J8*$T8 -> 2820 | Z8: =K8*$T8 -> 660 | AA8: =L8*$T8 -> 3426 | AB8: =M8*$T8 -> 1416 | ... AF8: =Q8*$T8 -> 492 | AG8: =SUM(U8:AF8) -> 16812 | AH8: Mint | AI8: =B8&" "&AH8&"" -> Al Fakher Mint | AJ8: =R8 -> 2802 | AK8: =AG8 -> 16812 | AL8: =AG8/$AG$126 -> 0.00372771
